return {{["y"] = 0, ["x"] = 1, ["name"] = "mcl_core:tree", ["z"] = 38, ["meta"] = {["inventory"] = {}, ["fields"] = {}}, ["param2"] = 1, ["param1"] = 0}, {["y"] = 0, ["x"] = 1, ["name"] = "mcl_core:tree", ["z"] = 39, ["meta"] = {["inventory"] = {}, ["fields"] = {}}, ["param2"] = 1, ["param1"] = 0}, {["y"] = 0, ["x"] = 1, ["name"] = "mcl_core:tree", ["z"] = 40, ["meta"] = {["inventory"] = {}, ["fields"] = {}}, ["param2"] = 1, ["param1"] = 0}, {["y"] = 0, ["x"] = 1, ["name"] = "mcl_core:tree", ["z"] = 41, ["meta"] = {["inventory"] = {}, ["fields"] = {}}, ["param2"] = 1, ["param1"] = 0}, {["y"] = 0, ["x"] = 1, ["name"] = "mcl_core:tree", ["z"] = 42, ["meta"] = {["inventory"] = {}, ["fields"] = {}}, ["param2"] = 1, ["param1"] = 0}, {["y"] = 0, ["x"] = 1, ["name"] = "mcl_core:tree", ["z"] = 43, ["meta"] = {["inventory"] = {}, ["fields"] = {}}, ["param2"] = 1, ["param1"] = 0}, {["y"] = 0, ["x"] = 1, ["name"] = "mcl_core:tree", ["z"] = 44, ["meta"] = {["inventory"] = {}, ["fields"] = {}}, ["param2"] = 1, ["param1"] = 0}, {["y"] = 0, ["x"] = 2, ["name"] = "mcl_core:tree", ["z"] = 38, ["meta"] = {["inventory"] = {}, ["fields"] = {}}, ["param2"] = 2, ["param1"] = 0}, {["y"] = 0, ["x"] = 2, ["name"] = "mcl_farming:soil_wet", ["z"] = 39, ["meta"] = {["inventory"] = {}, ["fields"] = {}}, ["param2"] = 0, ["param1"] = 13}, {["y"] = 0, ["x"] = 2, ["name"] = "mcl_farming:soil_wet", ["z"] = 40, ["meta"] = {["inventory"] = {}, ["fields"] = {}}, ["param2"] = 0, ["param1"] = 13}, {["y"] = 0, ["x"] = 2, ["name"] = "mcl_core:water_source", ["z"] = 41, ["meta"] = {["inventory"] = {}, ["fields"] = {}}, ["param2"] = 0, ["param1"] = 13}, {["y"] = 0, ["x"] = 2, ["name"] = "mcl_farming:soil_wet", ["z"] = 42, ["meta"] = {["inventory"] = {}, ["fields"] = {}}, ["param2"] = 0, ["param1"] = 13}, {["y"] = 0, ["x"] = 2, ["name"] = "mcl_farming:soil_wet", ["z"] = 43, ["meta"] = {["inventory"] = {}, ["fields"] = {}}, ["param2"] = 0, ["param1"] = 13}, {["y"] = 0, ["x"] = 2, ["name"] = "mcl_core:tree", ["z"] = 44, ["meta"] = {["inventory"] = {}, ["fields"] = {}}, ["param2"] = 1, ["param1"] = 0}, {["y"] = 1, ["x"] = 2, ["name"] = "mcl_farming:wheat", ["z"] = 39, ["meta"] = {["inventory"] = {}, ["fields"] = {}}, ["param2"] = 0, ["param1"] = 15}, {["y"] = 1, ["x"] = 2, ["name"] = "mcl_farming:wheat", ["z"] = 40, ["meta"] = {["inventory"] = {}, ["fields"] = {}}, ["param2"] = 0, ["param1"] = 15}, {["y"] = 1, ["x"] = 2, ["name"] = "mcl_farming:wheat", ["z"] = 42, ["meta"] = {["inventory"] = {}, ["fields"] = {}}, ["param2"] = 0, ["param1"] = 15}, {["y"] = 1, ["x"] = 2, ["name"] = "mcl_farming:wheat", ["z"] = 43, ["meta"] = {["inventory"] = {}, ["fields"] = {}}, ["param2"] = 0, ["param1"] = 15}, {["y"] = 0, ["x"] = 3, ["name"] = "mcl_core:tree", ["z"] = 38, ["meta"] = {["inventory"] = {}, ["fields"] = {}}, ["param2"] = 2, ["param1"] = 0}, {["y"] = 0, ["x"] = 3, ["name"] = "mcl_farming:soil_wet", ["z"] = 39, ["meta"] = {["inventory"] = {}, ["fields"] = {}}, ["param2"] = 0, ["param1"] = 13}, {["y"] = 0, ["x"] = 3, ["name"] = "mcl_farming:soil_wet", ["z"] = 40, ["meta"] = {["inventory"] = {}, ["fields"] = {}}, ["param2"] = 0, ["param1"] = 13}, {["y"] = 0, ["x"] = 3, ["name"] = "mcl_core:water_source", ["z"] = 41, ["meta"] = {["inventory"] = {}, ["fields"] = {}}, ["param2"] = 0, ["param1"] = 13}, {["y"] = 0, ["x"] = 3, ["name"] = "mcl_farming:soil_wet", ["z"] = 42, ["meta"] = {["inventory"] = {}, ["fields"] = {}}, ["param2"] = 0, ["param1"] = 13}, {["y"] = 0, ["x"] = 3, ["name"] = "mcl_farming:soil_wet", ["z"] = 43, ["meta"] = {["inventory"] = {}, ["fields"] = {}}, ["param2"] = 0, ["param1"] = 13}, {["y"] = 0, ["x"] = 3, ["name"] = "mcl_core:tree", ["z"] = 44, ["meta"] = {["inventory"] = {}, ["fields"] = {}}, ["param2"] = 1, ["param1"] = 0}, {["y"] = 1, ["x"] = 3, ["name"] = "mcl_farming:wheat", ["z"] = 39, ["meta"] = {["inventory"] = {}, ["fields"] = {}}, ["param2"] = 0, ["param1"] = 15}, {["y"] = 1, ["x"] = 3, ["name"] = "mcl_farming:wheat", ["z"] = 40, ["meta"] = {["inventory"] = {}, ["fields"] = {}}, ["param2"] = 0, ["param1"] = 15}, {["y"] = 1, ["x"] = 3, ["name"] = "mcl_farming:wheat", ["z"] = 42, ["meta"] = {["inventory"] = {}, ["fields"] = {}}, ["param2"] = 0, ["param1"] = 15}, {["y"] = 1, ["x"] = 3, ["name"] = "mcl_farming:wheat", ["z"] = 43, ["meta"] = {["inventory"] = {}, ["fields"] = {}}, ["param2"] = 0, ["param1"] = 15}, {["y"] = 0, ["x"] = 4, ["name"] = "mcl_core:tree", ["z"] = 38, ["meta"] = {["inventory"] = {}, ["fields"] = {}}, ["param2"] = 2, ["param1"] = 0}, {["y"] = 0, ["x"] = 4, ["name"] = "mcl_farming:soil_wet", ["z"] = 39, ["meta"] = {["inventory"] = {}, ["fields"] = {}}, ["param2"] = 0, ["param1"] = 13}, {["y"] = 0, ["x"] = 4, ["name"] = "mcl_farming:soil_wet", ["z"] = 40, ["meta"] = {["inventory"] = {}, ["fields"] = {}}, ["param2"] = 0, ["param1"] = 13}, {["y"] = 0, ["x"] = 4, ["name"] = "mcl_core:water_source", ["z"] = 41, ["meta"] = {["inventory"] = {}, ["fields"] = {}}, ["param2"] = 240, ["param1"] = 15}, {["y"] = 0, ["x"] = 4, ["name"] = "mcl_farming:soil_wet", ["z"] = 42, ["meta"] = {["inventory"] = {}, ["fields"] = {}}, ["param2"] = 0, ["param1"] = 13}, {["y"] = 0, ["x"] = 4, ["name"] = "mcl_farming:soil_wet", ["z"] = 43, ["meta"] = {["inventory"] = {}, ["fields"] = {}}, ["param2"] = 0, ["param1"] = 13}, {["y"] = 0, ["x"] = 4, ["name"] = "mcl_core:tree", ["z"] = 44, ["meta"] = {["inventory"] = {}, ["fields"] = {}}, ["param2"] = 1, ["param1"] = 0}, {["y"] = 1, ["x"] = 4, ["name"] = "mcl_farming:wheat", ["z"] = 39, ["meta"] = {["inventory"] = {}, ["fields"] = {}}, ["param2"] = 0, ["param1"] = 15}, {["y"] = 1, ["x"] = 4, ["name"] = "mcl_farming:wheat", ["z"] = 40, ["meta"] = {["inventory"] = {}, ["fields"] = {}}, ["param2"] = 0, ["param1"] = 15}, {["y"] = 1, ["x"] = 4, ["name"] = "mcl_farming:wheat", ["z"] = 42, ["meta"] = {["inventory"] = {}, ["fields"] = {}}, ["param2"] = 0, ["param1"] = 15}, {["y"] = 1, ["x"] = 4, ["name"] = "mcl_farming:wheat", ["z"] = 43, ["meta"] = {["inventory"] = {}, ["fields"] = {}}, ["param2"] = 0, ["param1"] = 15}, {["y"] = 0, ["x"] = 5, ["name"] = "mcl_core:tree", ["z"] = 38, ["meta"] = {["inventory"] = {}, ["fields"] = {}}, ["param2"] = 2, ["param1"] = 0}, {["y"] = 0, ["x"] = 5, ["name"] = "mcl_farming:soil_wet", ["z"] = 39, ["meta"] = {["inventory"] = {}, ["fields"] = {}}, ["param2"] = 0, ["param1"] = 13}, {["y"] = 0, ["x"] = 5, ["name"] = "mcl_farming:soil_wet", ["z"] = 40, ["meta"] = {["inventory"] = {}, ["fields"] = {}}, ["param2"] = 0, ["param1"] = 13}, {["y"] = 0, ["x"] = 5, ["name"] = "mcl_core:water_source", ["z"] = 41, ["meta"] = {["inventory"] = {}, ["fields"] = {}}, ["param2"] = 0, ["param1"] = 13}, {["y"] = 0, ["x"] = 5, ["name"] = "mcl_farming:soil_wet", ["z"] = 42, ["meta"] = {["inventory"] = {}, ["fields"] = {}}, ["param2"] = 0, ["param1"] = 13}, {["y"] = 0, ["x"] = 5, ["name"] = "mcl_farming:soil_wet", ["z"] = 43, ["meta"] = {["inventory"] = {}, ["fields"] = {}}, ["param2"] = 0, ["param1"] = 13}, {["y"] = 0, ["x"] = 5, ["name"] = "mcl_core:tree", ["z"] = 44, ["meta"] = {["inventory"] = {}, ["fields"] = {}}, ["param2"] = 1, ["param1"] = 0}, {["y"] = 1, ["x"] = 5, ["name"] = "mcl_farming:wheat", ["z"] = 39, ["meta"] = {["inventory"] = {}, ["fields"] = {}}, ["param2"] = 0, ["param1"] = 15}, {["y"] = 1, ["x"] = 5, ["name"] = "mcl_farming:wheat", ["z"] = 40, ["meta"] = {["inventory"] = {}, ["fields"] = {}}, ["param2"] = 0, ["param1"] = 15}, {["y"] = 1, ["x"] = 5, ["name"] = "mcl_farming:wheat", ["z"] = 42, ["meta"] = {["inventory"] = {}, ["fields"] = {}}, ["param2"] = 0, ["param1"] = 15}, {["y"] = 1, ["x"] = 5, ["name"] = "mcl_farming:wheat", ["z"] = 43, ["meta"] = {["inventory"] = {}, ["fields"] = {}}, ["param2"] = 0, ["param1"] = 15}, {["y"] = 0, ["x"] = 6, ["name"] = "mcl_core:tree", ["z"] = 38, ["meta"] = {["inventory"] = {}, ["fields"] = {}}, ["param2"] = 2, ["param1"] = 0}, {["y"] = 0, ["x"] = 6, ["name"] = "mcl_farming:soil_wet", ["z"] = 39, ["meta"] = {["inventory"] = {}, ["fields"] = {}}, ["param2"] = 0, ["param1"] = 13}, {["y"] = 0, ["x"] = 6, ["name"] = "mcl_farming:soil_wet", ["z"] = 40, ["meta"] = {["inventory"] = {}, ["fields"] = {}}, ["param2"] = 0, ["param1"] = 13}, {["y"] = 0, ["x"] = 6, ["name"] = "mcl_core:water_source", ["z"] = 41, ["meta"] = {["inventory"] = {}, ["fields"] = {}}, ["param2"] = 240, ["param1"] = 15}, {["y"] = 0, ["x"] = 6, ["name"] = "mcl_farming:soil_wet", ["z"] = 42, ["meta"] = {["inventory"] = {}, ["fields"] = {}}, ["param2"] = 0, ["param1"] = 13}, {["y"] = 0, ["x"] = 6, ["name"] = "mcl_farming:soil_wet", ["z"] = 43, ["meta"] = {["inventory"] = {}, ["fields"] = {}}, ["param2"] = 0, ["param1"] = 13}, {["y"] = 0, ["x"] = 6, ["name"] = "mcl_core:tree", ["z"] = 44, ["meta"] = {["inventory"] = {}, ["fields"] = {}}, ["param2"] = 1, ["param1"] = 0}, {["y"] = 1, ["x"] = 6, ["name"] = "mcl_farming:wheat", ["z"] = 39, ["meta"] = {["inventory"] = {}, ["fields"] = {}}, ["param2"] = 0, ["param1"] = 15}, {["y"] = 1, ["x"] = 6, ["name"] = "mcl_farming:wheat", ["z"] = 40, ["meta"] = {["inventory"] = {}, ["fields"] = {}}, ["param2"] = 0, ["param1"] = 15}, {["y"] = 1, ["x"] = 6, ["name"] = "mcl_farming:wheat", ["z"] = 42, ["meta"] = {["inventory"] = {}, ["fields"] = {}}, ["param2"] = 0, ["param1"] = 15}, {["y"] = 1, ["x"] = 6, ["name"] = "mcl_farming:wheat", ["z"] = 43, ["meta"] = {["inventory"] = {}, ["fields"] = {}}, ["param2"] = 0, ["param1"] = 15}, {["y"] = 0, ["x"] = 7, ["name"] = "mcl_core:tree", ["z"] = 38, ["meta"] = {["inventory"] = {}, ["fields"] = {}}, ["param2"] = 2, ["param1"] = 0}, {["y"] = 0, ["x"] = 7, ["name"] = "mcl_farming:soil_wet", ["z"] = 39, ["meta"] = {["inventory"] = {}, ["fields"] = {}}, ["param2"] = 0, ["param1"] = 13}, {["y"] = 0, ["x"] = 7, ["name"] = "mcl_farming:soil_wet", ["z"] = 40, ["meta"] = {["inventory"] = {}, ["fields"] = {}}, ["param2"] = 0, ["param1"] = 13}, {["y"] = 0, ["x"] = 7, ["name"] = "mcl_core:water_source", ["z"] = 41, ["meta"] = {["inventory"] = {}, ["fields"] = {}}, ["param2"] = 0, ["param1"] = 13}, {["y"] = 0, ["x"] = 7, ["name"] = "mcl_farming:soil_wet", ["z"] = 42, ["meta"] = {["inventory"] = {}, ["fields"] = {}}, ["param2"] = 0, ["param1"] = 13}, {["y"] = 0, ["x"] = 7, ["name"] = "mcl_farming:soil_wet", ["z"] = 43, ["meta"] = {["inventory"] = {}, ["fields"] = {}}, ["param2"] = 0, ["param1"] = 13}, {["y"] = 0, ["x"] = 7, ["name"] = "mcl_core:tree", ["z"] = 44, ["meta"] = {["inventory"] = {}, ["fields"] = {}}, ["param2"] = 1, ["param1"] = 0}, {["y"] = 1, ["x"] = 7, ["name"] = "mcl_farming:wheat", ["z"] = 39, ["meta"] = {["inventory"] = {}, ["fields"] = {}}, ["param2"] = 0, ["param1"] = 15}, {["y"] = 1, ["x"] = 7, ["name"] = "mcl_farming:wheat", ["z"] = 40, ["meta"] = {["inventory"] = {}, ["fields"] = {}}, ["param2"] = 0, ["param1"] = 15}, {["y"] = 1, ["x"] = 7, ["name"] = "mcl_farming:wheat", ["z"] = 42, ["meta"] = {["inventory"] = {}, ["fields"] = {}}, ["param2"] = 0, ["param1"] = 15}, {["y"] = 1, ["x"] = 7, ["name"] = "mcl_farming:wheat", ["z"] = 43, ["meta"] = {["inventory"] = {}, ["fields"] = {}}, ["param2"] = 0, ["param1"] = 15}, {["y"] = 0, ["x"] = 8, ["name"] = "mcl_core:tree", ["z"] = 38, ["meta"] = {["inventory"] = {}, ["fields"] = {}}, ["param2"] = 2, ["param1"] = 0}, {["y"] = 0, ["x"] = 8, ["name"] = "mcl_farming:soil_wet", ["z"] = 39, ["meta"] = {["inventory"] = {}, ["fields"] = {}}, ["param2"] = 0, ["param1"] = 13}, {["y"] = 0, ["x"] = 8, ["name"] = "mcl_farming:soil_wet", ["z"] = 40, ["meta"] = {["inventory"] = {}, ["fields"] = {}}, ["param2"] = 0, ["param1"] = 13}, {["y"] = 0, ["x"] = 8, ["name"] = "mcl_core:water_source", ["z"] = 41, ["meta"] = {["inventory"] = {}, ["fields"] = {}}, ["param2"] = 0, ["param1"] = 13}, {["y"] = 0, ["x"] = 8, ["name"] = "mcl_farming:soil_wet", ["z"] = 42, ["meta"] = {["inventory"] = {}, ["fields"] = {}}, ["param2"] = 0, ["param1"] = 13}, {["y"] = 0, ["x"] = 8, ["name"] = "mcl_farming:soil_wet", ["z"] = 43, ["meta"] = {["inventory"] = {}, ["fields"] = {}}, ["param2"] = 0, ["param1"] = 13}, {["y"] = 0, ["x"] = 8, ["name"] = "mcl_core:tree", ["z"] = 44, ["meta"] = {["inventory"] = {}, ["fields"] = {}}, ["param2"] = 1, ["param1"] = 0}, {["y"] = 1, ["x"] = 8, ["name"] = "mcl_farming:wheat", ["z"] = 39, ["meta"] = {["inventory"] = {}, ["fields"] = {}}, ["param2"] = 0, ["param1"] = 15}, {["y"] = 1, ["x"] = 8, ["name"] = "mcl_farming:wheat", ["z"] = 40, ["meta"] = {["inventory"] = {}, ["fields"] = {}}, ["param2"] = 0, ["param1"] = 15}, {["y"] = 1, ["x"] = 8, ["name"] = "mcl_farming:wheat", ["z"] = 42, ["meta"] = {["inventory"] = {}, ["fields"] = {}}, ["param2"] = 0, ["param1"] = 15}, {["y"] = 1, ["x"] = 8, ["name"] = "mcl_farming:wheat", ["z"] = 43, ["meta"] = {["inventory"] = {}, ["fields"] = {}}, ["param2"] = 0, ["param1"] = 15}, {["y"] = 0, ["x"] = 9, ["name"] = "mcl_core:tree", ["z"] = 38, ["meta"] = {["inventory"] = {}, ["fields"] = {}}, ["param2"] = 2, ["param1"] = 0}, {["y"] = 0, ["x"] = 9, ["name"] = "mcl_core:tree", ["z"] = 39, ["meta"] = {["inventory"] = {}, ["fields"] = {}}, ["param2"] = 3, ["param1"] = 0}, {["y"] = 0, ["x"] = 9, ["name"] = "mcl_core:tree", ["z"] = 40, ["meta"] = {["inventory"] = {}, ["fields"] = {}}, ["param2"] = 2, ["param1"] = 0}, {["y"] = 0, ["x"] = 9, ["name"] = "mcl_core:tree", ["z"] = 41, ["meta"] = {["inventory"] = {}, ["fields"] = {}}, ["param2"] = 3, ["param1"] = 0}, {["y"] = 0, ["x"] = 9, ["name"] = "mcl_core:tree", ["z"] = 42, ["meta"] = {["inventory"] = {}, ["fields"] = {}}, ["param2"] = 3, ["param1"] = 0}, {["y"] = 0, ["x"] = 9, ["name"] = "mcl_core:tree", ["z"] = 43, ["meta"] = {["inventory"] = {}, ["fields"] = {}}, ["param2"] = 3, ["param1"] = 0}, {["y"] = 0, ["x"] = 9, ["name"] = "mcl_core:tree", ["z"] = 44, ["meta"] = {["inventory"] = {}, ["fields"] = {}}, ["param2"] = 1, ["param1"] = 0}, {["y"] = 0, ["x"] = 10, ["name"] = "mcl_core:tree", ["z"] = 20, ["meta"] = {["inventory"] = {}, ["fields"] = {}}, ["param2"] = 0, ["param1"] = 0}, {["y"] = 0, ["x"] = 10, ["name"] = "mcl_core:tree", ["z"] = 21, ["meta"] = {["inventory"] = {}, ["fields"] = {}}, ["param2"] = 0, ["param1"] = 0}, {["y"] = 0, ["x"] = 10, ["name"] = "mcl_core:tree", ["z"] = 22, ["meta"] = {["inventory"] = {}, ["fields"] = {}}, ["param2"] = 0, ["param1"] = 0}, {["y"] = 0, ["x"] = 10, ["name"] = "mcl_core:tree", ["z"] = 23, ["meta"] = {["inventory"] = {}, ["fields"] = {}}, ["param2"] = 3, ["param1"] = 0}, {["y"] = 0, ["x"] = 10, ["name"] = "mcl_core:tree", ["z"] = 24, ["meta"] = {["inventory"] = {}, ["fields"] = {}}, ["param2"] = 0, ["param1"] = 0}, {["y"] = 0, ["x"] = 10, ["name"] = "mcl_core:tree", ["z"] = 25, ["meta"] = {["inventory"] = {}, ["fields"] = {}}, ["param2"] = 0, ["param1"] = 0}, {["y"] = 0, ["x"] = 10, ["name"] = "mcl_core:tree", ["z"] = 26, ["meta"] = {["inventory"] = {}, ["fields"] = {}}, ["param2"] = 1, ["param1"] = 0}, {["y"] = 0, ["x"] = 10, ["name"] = "mcl_core:tree", ["z"] = 27, ["meta"] = {["inventory"] = {}, ["fields"] = {}}, ["param2"] = 1, ["param1"] = 0}, {["y"] = 0, ["x"] = 10, ["name"] = "mcl_core:tree", ["z"] = 28, ["meta"] = {["inventory"] = {}, ["fields"] = {}}, ["param2"] = 2, ["param1"] = 0}, {["y"] = 0, ["x"] = 11, ["name"] = "mcl_core:tree", ["z"] = 20, ["meta"] = {["inventory"] = {}, ["fields"] = {}}, ["param2"] = 0, ["param1"] = 0}, {["y"] = 0, ["x"] = 11, ["name"] = "mcl_farming:soil_wet", ["z"] = 21, ["meta"] = {["inventory"] = {}, ["fields"] = {}}, ["param2"] = 0, ["param1"] = 13}, {["y"] = 0, ["x"] = 11, ["name"] = "mcl_farming:soil_wet", ["z"] = 22, ["meta"] = {["inventory"] = {}, ["fields"] = {}}, ["param2"] = 0, ["param1"] = 13}, {["y"] = 0, ["x"] = 11, ["name"] = "mcl_farming:soil_wet", ["z"] = 23, ["meta"] = {["inventory"] = {}, ["fields"] = {}}, ["param2"] = 0, ["param1"] = 13}, {["y"] = 0, ["x"] = 11, ["name"] = "mcl_farming:soil_wet", ["z"] = 24, ["meta"] = {["inventory"] = {}, ["fields"] = {}}, ["param2"] = 0, ["param1"] = 13}, {["y"] = 0, ["x"] = 11, ["name"] = "mcl_farming:soil_wet", ["z"] = 25, ["meta"] = {["inventory"] = {}, ["fields"] = {}}, ["param2"] = 0, ["param1"] = 29}, {["y"] = 0, ["x"] = 11, ["name"] = "mcl_farming:soil_wet", ["z"] = 26, ["meta"] = {["inventory"] = {}, ["fields"] = {}}, ["param2"] = 0, ["param1"] = 45}, {["y"] = 0, ["x"] = 11, ["name"] = "mcl_farming:soil_wet", ["z"] = 27, ["meta"] = {["inventory"] = {}, ["fields"] = {}}, ["param2"] = 0, ["param1"] = 61}, {["y"] = 0, ["x"] = 11, ["name"] = "mcl_core:tree", ["z"] = 28, ["meta"] = {["inventory"] = {}, ["fields"] = {}}, ["param2"] = 2, ["param1"] = 0}, {["y"] = 1, ["x"] = 11, ["name"] = "mcl_farming:wheat", ["z"] = 21, ["meta"] = {["inventory"] = {}, ["fields"] = {}}, ["param2"] = 0, ["param1"] = 15}, {["y"] = 1, ["x"] = 11, ["name"] = "mcl_farming:wheat", ["z"] = 22, ["meta"] = {["inventory"] = {}, ["fields"] = {}}, ["param2"] = 0, ["param1"] = 15}, {["y"] = 1, ["x"] = 11, ["name"] = "mcl_farming:wheat", ["z"] = 23, ["meta"] = {["inventory"] = {}, ["fields"] = {}}, ["param2"] = 0, ["param1"] = 15}, {["y"] = 1, ["x"] = 11, ["name"] = "mcl_farming:wheat", ["z"] = 24, ["meta"] = {["inventory"] = {}, ["fields"] = {}}, ["param2"] = 0, ["param1"] = 31}, {["y"] = 1, ["x"] = 11, ["name"] = "mcl_farming:wheat", ["z"] = 25, ["meta"] = {["inventory"] = {}, ["fields"] = {}}, ["param2"] = 0, ["param1"] = 47}, {["y"] = 1, ["x"] = 11, ["name"] = "mcl_farming:wheat", ["z"] = 26, ["meta"] = {["inventory"] = {}, ["fields"] = {}}, ["param2"] = 0, ["param1"] = 63}, {["y"] = 1, ["x"] = 11, ["name"] = "mcl_farming:wheat", ["z"] = 27, ["meta"] = {["inventory"] = {}, ["fields"] = {}}, ["param2"] = 0, ["param1"] = 79}, {["y"] = 0, ["x"] = 12, ["name"] = "mcl_core:tree", ["z"] = 20, ["meta"] = {["inventory"] = {}, ["fields"] = {}}, ["param2"] = 0, ["param1"] = 0}, {["y"] = 0, ["x"] = 12, ["name"] = "mcl_farming:soil_wet", ["z"] = 21, ["meta"] = {["inventory"] = {}, ["fields"] = {}}, ["param2"] = 0, ["param1"] = 13}, {["y"] = 0, ["x"] = 12, ["name"] = "mcl_farming:soil_wet", ["z"] = 22, ["meta"] = {["inventory"] = {}, ["fields"] = {}}, ["param2"] = 0, ["param1"] = 13}, {["y"] = 0, ["x"] = 12, ["name"] = "mcl_farming:soil_wet", ["z"] = 23, ["meta"] = {["inventory"] = {}, ["fields"] = {}}, ["param2"] = 0, ["param1"] = 13}, {["y"] = 0, ["x"] = 12, ["name"] = "mcl_farming:soil_wet", ["z"] = 24, ["meta"] = {["inventory"] = {}, ["fields"] = {}}, ["param2"] = 0, ["param1"] = 29}, {["y"] = 0, ["x"] = 12, ["name"] = "mcl_farming:soil_wet", ["z"] = 25, ["meta"] = {["inventory"] = {}, ["fields"] = {}}, ["param2"] = 0, ["param1"] = 45}, {["y"] = 0, ["x"] = 12, ["name"] = "mcl_farming:soil_wet", ["z"] = 26, ["meta"] = {["inventory"] = {}, ["fields"] = {}}, ["param2"] = 0, ["param1"] = 61}, {["y"] = 0, ["x"] = 12, ["name"] = "mcl_farming:soil_wet", ["z"] = 27, ["meta"] = {["inventory"] = {}, ["fields"] = {}}, ["param2"] = 0, ["param1"] = 77}, {["y"] = 0, ["x"] = 12, ["name"] = "mcl_core:tree", ["z"] = 28, ["meta"] = {["inventory"] = {}, ["fields"] = {}}, ["param2"] = 2, ["param1"] = 0}, {["y"] = 1, ["x"] = 12, ["name"] = "mcl_farming:wheat", ["z"] = 21, ["meta"] = {["inventory"] = {}, ["fields"] = {}}, ["param2"] = 0, ["param1"] = 15}, {["y"] = 1, ["x"] = 12, ["name"] = "mcl_farming:wheat", ["z"] = 22, ["meta"] = {["inventory"] = {}, ["fields"] = {}}, ["param2"] = 0, ["param1"] = 15}, {["y"] = 1, ["x"] = 12, ["name"] = "mcl_farming:wheat", ["z"] = 23, ["meta"] = {["inventory"] = {}, ["fields"] = {}}, ["param2"] = 0, ["param1"] = 31}, {["y"] = 1, ["x"] = 12, ["name"] = "mcl_farming:wheat_3", ["z"] = 24, ["meta"] = {["inventory"] = {}, ["fields"] = {}}, ["param2"] = 0, ["param1"] = 47}, {["y"] = 1, ["x"] = 12, ["name"] = "mcl_farming:wheat", ["z"] = 25, ["meta"] = {["inventory"] = {}, ["fields"] = {}}, ["param2"] = 0, ["param1"] = 63}, {["y"] = 1, ["x"] = 12, ["name"] = "mcl_farming:wheat", ["z"] = 26, ["meta"] = {["inventory"] = {}, ["fields"] = {}}, ["param2"] = 0, ["param1"] = 79}, {["y"] = 1, ["x"] = 12, ["name"] = "mcl_farming:wheat", ["z"] = 27, ["meta"] = {["inventory"] = {}, ["fields"] = {}}, ["param2"] = 0, ["param1"] = 95}, {["y"] = 3, ["x"] = 12, ["name"] = "mcl_torches:torch_wall", ["z"] = 50, ["meta"] = {["inventory"] = {}, ["fields"] = {}}, ["param2"] = 1, ["param1"] = 15}, {["y"] = 0, ["x"] = 13, ["name"] = "mcl_core:tree", ["z"] = 20, ["meta"] = {["inventory"] = {}, ["fields"] = {}}, ["param2"] = 0, ["param1"] = 0}, {["y"] = 0, ["x"] = 13, ["name"] = "mcl_core:water_source", ["z"] = 21, ["meta"] = {["inventory"] = {}, ["fields"] = {}}, ["param2"] = 0, ["param1"] = 13}, {["y"] = 0, ["x"] = 13, ["name"] = "mcl_core:water_source", ["z"] = 22, ["meta"] = {["inventory"] = {}, ["fields"] = {}}, ["param2"] = 0, ["param1"] = 13}, {["y"] = 0, ["x"] = 13, ["name"] = "mcl_core:water_source", ["z"] = 23, ["meta"] = {["inventory"] = {}, ["fields"] = {}}, ["param2"] = 0, ["param1"] = 29}, {["y"] = 0, ["x"] = 13, ["name"] = "mcl_core:water_source", ["z"] = 24, ["meta"] = {["inventory"] = {}, ["fields"] = {}}, ["param2"] = 240, ["param1"] = 47}, {["y"] = 0, ["x"] = 13, ["name"] = "mcl_core:water_source", ["z"] = 25, ["meta"] = {["inventory"] = {}, ["fields"] = {}}, ["param2"] = 0, ["param1"] = 61}, {["y"] = 0, ["x"] = 13, ["name"] = "mcl_core:water_source", ["z"] = 26, ["meta"] = {["inventory"] = {}, ["fields"] = {}}, ["param2"] = 0, ["param1"] = 77}, {["y"] = 0, ["x"] = 13, ["name"] = "mcl_core:water_source", ["z"] = 27, ["meta"] = {["inventory"] = {}, ["fields"] = {}}, ["param2"] = 0, ["param1"] = 93}, {["y"] = 0, ["x"] = 13, ["name"] = "mcl_core:tree", ["z"] = 28, ["meta"] = {["inventory"] = {}, ["fields"] = {}}, ["param2"] = 2, ["param1"] = 0}, {["y"] = 0, ["x"] = 13, ["name"] = "mcl_fences:fence", ["z"] = 50, ["meta"] = {["inventory"] = {}, ["fields"] = {}}, ["param2"] = 0, ["param1"] = 157}, {["y"] = 1, ["x"] = 13, ["name"] = "mcl_fences:fence", ["z"] = 50, ["meta"] = {["inventory"] = {}, ["fields"] = {}}, ["param2"] = 0, ["param1"] = 173}, {["y"] = 2, ["x"] = 13, ["name"] = "mcl_fences:fence", ["z"] = 50, ["meta"] = {["inventory"] = {}, ["fields"] = {}}, ["param2"] = 0, ["param1"] = 189}, {["y"] = 3, ["x"] = 13, ["name"] = "mcl_torches:torch_wall", ["z"] = 49, ["meta"] = {["inventory"] = {}, ["fields"] = {}}, ["param2"] = 0, ["param1"] = 15}, {["y"] = 3, ["x"] = 13, ["name"] = "mcl_wool:black", ["z"] = 50, ["meta"] = {["inventory"] = {}, ["fields"] = {}}, ["param2"] = 0, ["param1"] = 0}, {["y"] = 3, ["x"] = 13, ["name"] = "mcl_torches:torch_wall", ["z"] = 51, ["meta"] = {["inventory"] = {}, ["fields"] = {}}, ["param2"] = 2, ["param1"] = 15}, {["y"] = 0, ["x"] = 14, ["name"] = "mcl_core:tree", ["z"] = 20, ["meta"] = {["inventory"] = {}, ["fields"] = {}}, ["param2"] = 0, ["param1"] = 0}, {["y"] = 0, ["x"] = 14, ["name"] = "mcl_farming:soil_wet", ["z"] = 21, ["meta"] = {["inventory"] = {}, ["fields"] = {}}, ["param2"] = 0, ["param1"] = 13}, {["y"] = 0, ["x"] = 14, ["name"] = "mcl_farming:soil_wet", ["z"] = 22, ["meta"] = {["inventory"] = {}, ["fields"] = {}}, ["param2"] = 0, ["param1"] = 29}, {["y"] = 0, ["x"] = 14, ["name"] = "mcl_farming:soil_wet", ["z"] = 23, ["meta"] = {["inventory"] = {}, ["fields"] = {}}, ["param2"] = 0, ["param1"] = 45}, {["y"] = 0, ["x"] = 14, ["name"] = "mcl_farming:soil_wet", ["z"] = 24, ["meta"] = {["inventory"] = {}, ["fields"] = {}}, ["param2"] = 0, ["param1"] = 61}, {["y"] = 0, ["x"] = 14, ["name"] = "mcl_farming:soil_wet", ["z"] = 25, ["meta"] = {["inventory"] = {}, ["fields"] = {}}, ["param2"] = 0, ["param1"] = 77}, {["y"] = 0, ["x"] = 14, ["name"] = "mcl_farming:soil_wet", ["z"] = 26, ["meta"] = {["inventory"] = {}, ["fields"] = {}}, ["param2"] = 0, ["param1"] = 93}, {["y"] = 0, ["x"] = 14, ["name"] = "mcl_farming:soil_wet", ["z"] = 27, ["meta"] = {["inventory"] = {}, ["fields"] = {}}, ["param2"] = 0, ["param1"] = 109}, {["y"] = 0, ["x"] = 14, ["name"] = "mcl_core:tree", ["z"] = 28, ["meta"] = {["inventory"] = {}, ["fields"] = {}}, ["param2"] = 3, ["param1"] = 0}, {["y"] = 0, ["x"] = 14, ["name"] = "mcl_core:cobble", ["z"] = 36, ["meta"] = {["inventory"] = {}, ["fields"] = {}}, ["param2"] = 0, ["param1"] = 0}, {["y"] = 0, ["x"] = 14, ["name"] = "mcl_core:cobble", ["z"] = 37, ["meta"] = {["inventory"] = {}, ["fields"] = {}}, ["param2"] = 0, ["param1"] = 0}, {["y"] = 0, ["x"] = 14, ["name"] = "mcl_core:cobble", ["z"] = 38, ["meta"] = {["inventory"] = {}, ["fields"] = {}}, ["param2"] = 0, ["param1"] = 0}, {["y"] = 0, ["x"] = 14, ["name"] = "mcl_core:cobble", ["z"] = 39, ["meta"] = {["inventory"] = {}, ["fields"] = {}}, ["param2"] = 0, ["param1"] = 0}, {["y"] = 1, ["x"] = 14, ["name"] = "mcl_farming:wheat", ["z"] = 21, ["meta"] = {["inventory"] = {}, ["fields"] = {}}, ["param2"] = 0, ["param1"] = 31}, {["y"] = 1, ["x"] = 14, ["name"] = "mcl_farming:wheat", ["z"] = 22, ["meta"] = {["inventory"] = {}, ["fields"] = {}}, ["param2"] = 0, ["param1"] = 47}, {["y"] = 1, ["x"] = 14, ["name"] = "mcl_farming:wheat", ["z"] = 23, ["meta"] = {["inventory"] = {}, ["fields"] = {}}, ["param2"] = 0, ["param1"] = 63}, {["y"] = 1, ["x"] = 14, ["name"] = "mcl_farming:wheat", ["z"] = 24, ["meta"] = {["inventory"] = {}, ["fields"] = {}}, ["param2"] = 0, ["param1"] = 79}, {["y"] = 1, ["x"] = 14, ["name"] = "mcl_farming:wheat", ["z"] = 25, ["meta"] = {["inventory"] = {}, ["fields"] = {}}, ["param2"] = 0, ["param1"] = 95}, {["y"] = 1, ["x"] = 14, ["name"] = "mcl_farming:wheat", ["z"] = 26, ["meta"] = {["inventory"] = {}, ["fields"] = {}}, ["param2"] = 0, ["param1"] = 111}, {["y"] = 1, ["x"] = 14, ["name"] = "mcl_farming:wheat", ["z"] = 27, ["meta"] = {["inventory"] = {}, ["fields"] = {}}, ["param2"] = 0, ["param1"] = 127}, {["y"] = 1, ["x"] = 14, ["name"] = "mcl_core:cobble", ["z"] = 33, ["meta"] = {["inventory"] = {}, ["fields"] = {}}, ["param2"] = 0, ["param1"] = 0}, {["y"] = 1, ["x"] = 14, ["name"] = "mcl_core:cobble", ["z"] = 34, ["meta"] = {["inventory"] = {}, ["fields"] = {}}, ["param2"] = 0, ["param1"] = 0}, {["y"] = 1, ["x"] = 14, ["name"] = "mcl_core:cobble", ["z"] = 35, ["meta"] = {["inventory"] = {}, ["fields"] = {}}, ["param2"] = 0, ["param1"] = 0}, {["y"] = 1, ["x"] = 14, ["name"] = "mcl_core:cobble", ["z"] = 36, ["meta"] = {["inventory"] = {}, ["fields"] = {}}, ["param2"] = 0, ["param1"] = 0}, {["y"] = 1, ["x"] = 14, ["name"] = "mcl_core:cobble", ["z"] = 37, ["meta"] = {["inventory"] = {}, ["fields"] = {}}, ["param2"] = 0, ["param1"] = 0}, {["y"] = 1, ["x"] = 14, ["name"] = "mcl_core:cobble", ["z"] = 38, ["meta"] = {["inventory"] = {}, ["fields"] = {}}, ["param2"] = 0, ["param1"] = 0}, {["y"] = 1, ["x"] = 14, ["name"] = "mcl_core:cobble", ["z"] = 39, ["meta"] = {["inventory"] = {}, ["fields"] = {}}, ["param2"] = 0, ["param1"] = 0}, {["y"] = 2, ["x"] = 14, ["name"] = "mcl_core:cobble", ["z"] = 33, ["meta"] = {["inventory"] = {}, ["fields"] = {}}, ["param2"] = 0, ["param1"] = 0}, {["y"] = 2, ["x"] = 14, ["name"] = "xpanes:pane_natural", ["z"] = 34, ["meta"] = {["inventory"] = {}, ["fields"] = {}}, ["param2"] = 0, ["param1"] = 157}, {["y"] = 2, ["x"] = 14, ["name"] = "mcl_core:cobble", ["z"] = 35, ["meta"] = {["inventory"] = {}, ["fields"] = {}}, ["param2"] = 0, ["param1"] = 0}, {["y"] = 2, ["x"] = 14, ["name"] = "mcl_core:cobble", ["z"] = 36, ["meta"] = {["inventory"] = {}, ["fields"] = {}}, ["param2"] = 0, ["param1"] = 0}, {["y"] = 2, ["x"] = 14, ["name"] = "mcl_core:cobble", ["z"] = 37, ["meta"] = {["inventory"] = {}, ["fields"] = {}}, ["param2"] = 0, ["param1"] = 0}, {["y"] = 2, ["x"] = 14, ["name"] = "mcl_core:cobble", ["z"] = 38, ["meta"] = {["inventory"] = {}, ["fields"] = {}}, ["param2"] = 0, ["param1"] = 0}, {["y"] = 2, ["x"] = 14, ["name"] = "mcl_core:cobble", ["z"] = 39, ["meta"] = {["inventory"] = {}, ["fields"] = {}}, ["param2"] = 0, ["param1"] = 0}, {["y"] = 3, ["x"] = 14, ["name"] = "mcl_core:cobble", ["z"] = 33, ["meta"] = {["inventory"] = {}, ["fields"] = {}}, ["param2"] = 0, ["param1"] = 0}, {["y"] = 3, ["x"] = 14, ["name"] = "xpanes:pane_natural", ["z"] = 34, ["meta"] = {["inventory"] = {}, ["fields"] = {}}, ["param2"] = 0, ["param1"] = 173}, {["y"] = 3, ["x"] = 14, ["name"] = "mcl_core:cobble", ["z"] = 35, ["meta"] = {["inventory"] = {}, ["fields"] = {}}, ["param2"] = 0, ["param1"] = 0}, {["y"] = 3, ["x"] = 14, ["name"] = "mcl_core:cobble", ["z"] = 36, ["meta"] = {["inventory"] = {}, ["fields"] = {}}, ["param2"] = 0, ["param1"] = 0}, {["y"] = 3, ["x"] = 14, ["name"] = "mcl_core:cobble", ["z"] = 37, ["meta"] = {["inventory"] = {}, ["fields"] = {}}, ["param2"] = 0, ["param1"] = 0}, {["y"] = 3, ["x"] = 14, ["name"] = "xpanes:pane_natural", ["z"] = 38, ["meta"] = {["inventory"] = {}, ["fields"] = {}}, ["param2"] = 0, ["param1"] = 157}, {["y"] = 3, ["x"] = 14, ["name"] = "mcl_core:cobble", ["z"] = 39, ["meta"] = {["inventory"] = {}, ["fields"] = {}}, ["param2"] = 0, ["param1"] = 0}, {["y"] = 3, ["x"] = 14, ["name"] = "mcl_torches:torch_wall", ["z"] = 50, ["meta"] = {["inventory"] = {}, ["fields"] = {}}, ["param2"] = 3, ["param1"] = 15}, {["y"] = 4, ["x"] = 14, ["name"] = "mcl_core:cobble", ["z"] = 32, ["meta"] = {["inventory"] = {}, ["fields"] = {}}, ["param2"] = 0, ["param1"] = 0}, {["y"] = 4, ["x"] = 14, ["name"] = "mcl_core:cobble", ["z"] = 33, ["meta"] = {["inventory"] = {}, ["fields"] = {}}, ["param2"] = 0, ["param1"] = 0}, {["y"] = 4, ["x"] = 14, ["name"] = "mcl_core:cobble", ["z"] = 34, ["meta"] = {["inventory"] = {}, ["fields"] = {}}, ["param2"] = 0, ["param1"] = 0}, {["y"] = 4, ["x"] = 14, ["name"] = "mcl_core:cobble", ["z"] = 35, ["meta"] = {["inventory"] = {}, ["fields"] = {}}, ["param2"] = 0, ["param1"] = 0}, {["y"] = 4, ["x"] = 14, ["name"] = "mcl_core:cobble", ["z"] = 36, ["meta"] = {["inventory"] = {}, ["fields"] = {}}, ["param2"] = 0, ["param1"] = 0}, {["y"] = 4, ["x"] = 14, ["name"] = "mcl_core:cobble", ["z"] = 37, ["meta"] = {["inventory"] = {}, ["fields"] = {}}, ["param2"] = 0, ["param1"] = 0}, {["y"] = 4, ["x"] = 14, ["name"] = "mcl_core:cobble", ["z"] = 38, ["meta"] = {["inventory"] = {}, ["fields"] = {}}, ["param2"] = 0, ["param1"] = 0}, {["y"] = 4, ["x"] = 14, ["name"] = "mcl_core:cobble", ["z"] = 39, ["meta"] = {["inventory"] = {}, ["fields"] = {}}, ["param2"] = 0, ["param1"] = 0}, {["y"] = 5, ["x"] = 14, ["name"] = "mcl_core:cobble", ["z"] = 33, ["meta"] = {["inventory"] = {}, ["fields"] = {}}, ["param2"] = 0, ["param1"] = 0}, {["y"] = 5, ["x"] = 14, ["name"] = "mcl_core:cobble", ["z"] = 34, ["meta"] = {["inventory"] = {}, ["fields"] = {}}, ["param2"] = 0, ["param1"] = 0}, {["y"] = 5, ["x"] = 14, ["name"] = "mcl_core:cobble", ["z"] = 35, ["meta"] = {["inventory"] = {}, ["fields"] = {}}, ["param2"] = 0, ["param1"] = 0}, {["y"] = 6, ["x"] = 14, ["name"] = "mcl_core:cobble", ["z"] = 33, ["meta"] = {["inventory"] = {}, ["fields"] = {}}, ["param2"] = 0, ["param1"] = 0}, {["y"] = 6, ["x"] = 14, ["name"] = "xpanes:pane_natural", ["z"] = 34, ["meta"] = {["inventory"] = {}, ["fields"] = {}}, ["param2"] = 0, ["param1"] = 93}, {["y"] = 6, ["x"] = 14, ["name"] = "mcl_core:cobble", ["z"] = 35, ["meta"] = {["inventory"] = {}, ["fields"] = {}}, ["param2"] = 0, ["param1"] = 0}, {["y"] = 7, ["x"] = 14, ["name"] = "mcl_core:cobble", ["z"] = 33, ["meta"] = {["inventory"] = {}, ["fields"] = {}}, ["param2"] = 0, ["param1"] = 0}, {["y"] = 7, ["x"] = 14, ["name"] = "xpanes:pane_natural", ["z"] = 34, ["meta"] = {["inventory"] = {}, ["fields"] = {}}, ["param2"] = 0, ["param1"] = 77}, {["y"] = 7, ["x"] = 14, ["name"] = "mcl_core:cobble", ["z"] = 35, ["meta"] = {["inventory"] = {}, ["fields"] = {}}, ["param2"] = 0, ["param1"] = 0}, {["y"] = 8, ["x"] = 14, ["name"] = "mcl_core:cobble", ["z"] = 33, ["meta"] = {["inventory"] = {}, ["fields"] = {}}, ["param2"] = 0, ["param1"] = 0}, {["y"] = 8, ["x"] = 14, ["name"] = "mcl_core:cobble", ["z"] = 34, ["meta"] = {["inventory"] = {}, ["fields"] = {}}, ["param2"] = 0, ["param1"] = 0}, {["y"] = 8, ["x"] = 14, ["name"] = "mcl_core:cobble", ["z"] = 35, ["meta"] = {["inventory"] = {}, ["fields"] = {}}, ["param2"] = 0, ["param1"] = 0}, {["y"] = 9, ["x"] = 14, ["name"] = "mcl_core:cobble", ["z"] = 32, ["meta"] = {["inventory"] = {}, ["fields"] = {}}, ["param2"] = 0, ["param1"] = 0}, {["y"] = 9, ["x"] = 14, ["name"] = "mcl_core:cobble", ["z"] = 33, ["meta"] = {["inventory"] = {}, ["fields"] = {}}, ["param2"] = 0, ["param1"] = 0}, {["y"] = 9, ["x"] = 14, ["name"] = "mcl_core:cobble", ["z"] = 34, ["meta"] = {["inventory"] = {}, ["fields"] = {}}, ["param2"] = 0, ["param1"] = 0}, {["y"] = 9, ["x"] = 14, ["name"] = "mcl_core:cobble", ["z"] = 35, ["meta"] = {["inventory"] = {}, ["fields"] = {}}, ["param2"] = 0, ["param1"] = 0}, {["y"] = 9, ["x"] = 14, ["name"] = "mcl_core:cobble", ["z"] = 36, ["meta"] = {["inventory"] = {}, ["fields"] = {}}, ["param2"] = 0, ["param1"] = 0}, {["y"] = 10, ["x"] = 14, ["name"] = "mcl_core:cobble", ["z"] = 33, ["meta"] = {["inventory"] = {}, ["fields"] = {}}, ["param2"] = 0, ["param1"] = 0}, {["y"] = 10, ["x"] = 14, ["name"] = "mcl_core:cobble", ["z"] = 34, ["meta"] = {["inventory"] = {}, ["fields"] = {}}, ["param2"] = 0, ["param1"] = 0}, {["y"] = 10, ["x"] = 14, ["name"] = "mcl_core:cobble", ["z"] = 35, ["meta"] = {["inventory"] = {}, ["fields"] = {}}, ["param2"] = 0, ["param1"] = 0}, {["y"] = 11, ["x"] = 14, ["name"] = "mcl_core:cobble", ["z"] = 34, ["meta"] = {["inventory"] = {}, ["fields"] = {}}, ["param2"] = 0, ["param1"] = 0}, {["y"] = 0, ["x"] = 15, ["name"] = "mcl_core:tree", ["z"] = 20, ["meta"] = {["inventory"] = {}, ["fields"] = {}}, ["param2"] = 0, ["param1"] = 0}, {["y"] = 0, ["x"] = 15, ["name"] = "mcl_farming:soil_wet", ["z"] = 21, ["meta"] = {["inventory"] = {}, ["fields"] = {}}, ["param2"] = 0, ["param1"] = 29}, {["y"] = 0, ["x"] = 15, ["name"] = "mcl_farming:soil_wet", ["z"] = 22, ["meta"] = {["inventory"] = {}, ["fields"] = {}}, ["param2"] = 0, ["param1"] = 45}, {["y"] = 0, ["x"] = 15, ["name"] = "mcl_farming:soil_wet", ["z"] = 23, ["meta"] = {["inventory"] = {}, ["fields"] = {}}, ["param2"] = 0, ["param1"] = 61}, {["y"] = 0, ["x"] = 15, ["name"] = "mcl_farming:soil_wet", ["z"] = 24, ["meta"] = {["inventory"] = {}, ["fields"] = {}}, ["param2"] = 0, ["param1"] = 77}, {["y"] = 0, ["x"] = 15, ["name"] = "mcl_farming:soil_wet", ["z"] = 25, ["meta"] = {["inventory"] = {}, ["fields"] = {}}, ["param2"] = 0, ["param1"] = 93}, {["y"] = 0, ["x"] = 15, ["name"] = "mcl_farming:soil_wet", ["z"] = 26, ["meta"] = {["inventory"] = {}, ["fields"] = {}}, ["param2"] = 0, ["param1"] = 109}, {["y"] = 0, ["x"] = 15, ["name"] = "mcl_farming:soil_wet", ["z"] = 27, ["meta"] = {["inventory"] = {}, ["fields"] = {}}, ["param2"] = 0, ["param1"] = 125}, {["y"] = 0, ["x"] = 15, ["name"] = "mcl_core:tree", ["z"] = 28, ["meta"] = {["inventory"] = {}, ["fields"] = {}}, ["param2"] = 3, ["param1"] = 0}, {["y"] = 0, ["x"] = 15, ["name"] = "mcl_core:cobble", ["z"] = 32, ["meta"] = {["inventory"] = {}, ["fields"] = {}}, ["param2"] = 0, ["param1"] = 0}, {["y"] = 0, ["x"] = 15, ["name"] = "mcl_core:cobble", ["z"] = 33, ["meta"] = {["inventory"] = {}, ["fields"] = {}}, ["param2"] = 0, ["param1"] = 0}, {["y"] = 0, ["x"] = 15, ["name"] = "mcl_core:cobble", ["z"] = 34, ["meta"] = {["inventory"] = {}, ["fields"] = {}}, ["param2"] = 0, ["param1"] = 0}, {["y"] = 0, ["x"] = 15, ["name"] = "mcl_core:cobble", ["z"] = 35, ["meta"] = {["inventory"] = {}, ["fields"] = {}}, ["param2"] = 0, ["param1"] = 0}, {["y"] = 0, ["x"] = 15, ["name"] = "mcl_core:cobble", ["z"] = 36, ["meta"] = {["inventory"] = {}, ["fields"] = {}}, ["param2"] = 0, ["param1"] = 0}, {["y"] = 0, ["x"] = 15, ["name"] = "mcl_core:cobble", ["z"] = 37, ["meta"] = {["inventory"] = {}, ["fields"] = {}}, ["param2"] = 0, ["param1"] = 0}, {["y"] = 0, ["x"] = 15, ["name"] = "mcl_core:cobble", ["z"] = 38, ["meta"] = {["inventory"] = {}, ["fields"] = {}}, ["param2"] = 0, ["param1"] = 0}, {["y"] = 0, ["x"] = 15, ["name"] = "mcl_core:cobble", ["z"] = 39, ["meta"] = {["inventory"] = {}, ["fields"] = {}}, ["param2"] = 0, ["param1"] = 0}, {["y"] = 0, ["x"] = 15, ["name"] = "mcl_core:cobble", ["z"] = 40, ["meta"] = {["inventory"] = {}, ["fields"] = {}}, ["param2"] = 0, ["param1"] = 0}, {["y"] = 1, ["x"] = 15, ["name"] = "mcl_farming:wheat", ["z"] = 21, ["meta"] = {["inventory"] = {}, ["fields"] = {}}, ["param2"] = 0, ["param1"] = 47}, {["y"] = 1, ["x"] = 15, ["name"] = "mcl_farming:wheat", ["z"] = 22, ["meta"] = {["inventory"] = {}, ["fields"] = {}}, ["param2"] = 0, ["param1"] = 63}, {["y"] = 1, ["x"] = 15, ["name"] = "mcl_farming:wheat", ["z"] = 23, ["meta"] = {["inventory"] = {}, ["fields"] = {}}, ["param2"] = 0, ["param1"] = 79}, {["y"] = 1, ["x"] = 15, ["name"] = "mcl_farming:wheat", ["z"] = 24, ["meta"] = {["inventory"] = {}, ["fields"] = {}}, ["param2"] = 0, ["param1"] = 95}, {["y"] = 1, ["x"] = 15, ["name"] = "mcl_farming:wheat", ["z"] = 25, ["meta"] = {["inventory"] = {}, ["fields"] = {}}, ["param2"] = 0, ["param1"] = 111}, {["y"] = 1, ["x"] = 15, ["name"] = "mcl_farming:wheat", ["z"] = 26, ["meta"] = {["inventory"] = {}, ["fields"] = {}}, ["param2"] = 0, ["param1"] = 127}, {["y"] = 1, ["x"] = 15, ["name"] = "mcl_farming:wheat_2", ["z"] = 27, ["meta"] = {["inventory"] = {}, ["fields"] = {}}, ["param2"] = 0, ["param1"] = 143}, {["y"] = 1, ["x"] = 15, ["name"] = "mcl_core:cobble", ["z"] = 32, ["meta"] = {["inventory"] = {}, ["fields"] = {}}, ["param2"] = 0, ["param1"] = 0}, {["y"] = 1, ["x"] = 15, ["name"] = "mcl_core:ladder", ["z"] = 35, ["meta"] = {["inventory"] = {}, ["fields"] = {}}, ["param2"] = 3, ["param1"] = 138}, {["y"] = 1, ["x"] = 15, ["name"] = "stairs:stair_cobble", ["z"] = 37, ["meta"] = {["inventory"] = {}, ["fields"] = {}}, ["param2"] = 0, ["param1"] = 121}, {["y"] = 1, ["x"] = 15, ["name"] = "mcl_core:cobble", ["z"] = 38, ["meta"] = {["inventory"] = {}, ["fields"] = {}}, ["param2"] = 0, ["param1"] = 0}, {["y"] = 1, ["x"] = 15, ["name"] = "mcl_core:cobble", ["z"] = 39, ["meta"] = {["inventory"] = {}, ["fields"] = {}}, ["param2"] = 0, ["param1"] = 0}, {["y"] = 1, ["x"] = 15, ["name"] = "mcl_core:cobble", ["z"] = 40, ["meta"] = {["inventory"] = {}, ["fields"] = {}}, ["param2"] = 0, ["param1"] = 0}, {["y"] = 2, ["x"] = 15, ["name"] = "mcl_core:cobble", ["z"] = 32, ["meta"] = {["inventory"] = {}, ["fields"] = {}}, ["param2"] = 0, ["param1"] = 0}, {["y"] = 2, ["x"] = 15, ["name"] = "mcl_core:ladder", ["z"] = 35, ["meta"] = {["inventory"] = {}, ["fields"] = {}}, ["param2"] = 3, ["param1"] = 155}, {["y"] = 2, ["x"] = 15, ["name"] = "stairs:stair_cobble", ["z"] = 39, ["meta"] = {["inventory"] = {}, ["fields"] = {}}, ["param2"] = 0, ["param1"] = 170}, {["y"] = 2, ["x"] = 15, ["name"] = "mcl_core:cobble", ["z"] = 40, ["meta"] = {["inventory"] = {}, ["fields"] = {}}, ["param2"] = 0, ["param1"] = 0}, {["y"] = 3, ["x"] = 15, ["name"] = "mcl_core:cobble", ["z"] = 32, ["meta"] = {["inventory"] = {}, ["fields"] = {}}, ["param2"] = 0, ["param1"] = 0}, {["y"] = 3, ["x"] = 15, ["name"] = "mcl_core:ladder", ["z"] = 35, ["meta"] = {["inventory"] = {}, ["fields"] = {}}, ["param2"] = 3, ["param1"] = 171}, {["y"] = 3, ["x"] = 15, ["name"] = "mcl_core:cobble", ["z"] = 40, ["meta"] = {["inventory"] = {}, ["fields"] = {}}, ["param2"] = 0, ["param1"] = 0}, {["y"] = 4, ["x"] = 15, ["name"] = "mcl_core:cobble", ["z"] = 32, ["meta"] = {["inventory"] = {}, ["fields"] = {}}, ["param2"] = 0, ["param1"] = 0}, {["y"] = 4, ["x"] = 15, ["name"] = "mcl_core:cobble", ["z"] = 33, ["meta"] = {["inventory"] = {}, ["fields"] = {}}, ["param2"] = 0, ["param1"] = 0}, {["y"] = 4, ["x"] = 15, ["name"] = "mcl_core:cobble", ["z"] = 34, ["meta"] = {["inventory"] = {}, ["fields"] = {}}, ["param2"] = 0, ["param1"] = 0}, {["y"] = 4, ["x"] = 15, ["name"] = "mcl_core:ladder", ["z"] = 35, ["meta"] = {["inventory"] = {}, ["fields"] = {}}, ["param2"] = 3, ["param1"] = 154}, {["y"] = 4, ["x"] = 15, ["name"] = "mcl_core:cobble", ["z"] = 36, ["meta"] = {["inventory"] = {}, ["fields"] = {}}, ["param2"] = 0, ["param1"] = 0}, {["y"] = 4, ["x"] = 15, ["name"] = "mcl_core:cobble", ["z"] = 40, ["meta"] = {["inventory"] = {}, ["fields"] = {}}, ["param2"] = 0, ["param1"] = 0}, {["y"] = 5, ["x"] = 15, ["name"] = "mcl_core:cobble", ["z"] = 32, ["meta"] = {["inventory"] = {}, ["fields"] = {}}, ["param2"] = 0, ["param1"] = 0}, {["y"] = 5, ["x"] = 15, ["name"] = "mcl_core:ladder", ["z"] = 35, ["meta"] = {["inventory"] = {}, ["fields"] = {}}, ["param2"] = 3, ["param1"] = 138}, {["y"] = 5, ["x"] = 15, ["name"] = "mcl_core:cobble", ["z"] = 36, ["meta"] = {["inventory"] = {}, ["fields"] = {}}, ["param2"] = 0, ["param1"] = 0}, {["y"] = 5, ["x"] = 15, ["name"] = "mcl_core:cobble", ["z"] = 37, ["meta"] = {["inventory"] = {}, ["fields"] = {}}, ["param2"] = 0, ["param1"] = 0}, {["y"] = 5, ["x"] = 15, ["name"] = "mcl_core:cobble", ["z"] = 38, ["meta"] = {["inventory"] = {}, ["fields"] = {}}, ["param2"] = 0, ["param1"] = 0}, {["y"] = 5, ["x"] = 15, ["name"] = "mcl_core:cobble", ["z"] = 39, ["meta"] = {["inventory"] = {}, ["fields"] = {}}, ["param2"] = 0, ["param1"] = 0}, {["y"] = 6, ["x"] = 15, ["name"] = "mcl_core:cobble", ["z"] = 32, ["meta"] = {["inventory"] = {}, ["fields"] = {}}, ["param2"] = 0, ["param1"] = 0}, {["y"] = 6, ["x"] = 15, ["name"] = "mcl_core:ladder", ["z"] = 35, ["meta"] = {["inventory"] = {}, ["fields"] = {}}, ["param2"] = 3, ["param1"] = 123}, {["y"] = 6, ["x"] = 15, ["name"] = "mcl_core:cobble", ["z"] = 36, ["meta"] = {["inventory"] = {}, ["fields"] = {}}, ["param2"] = 0, ["param1"] = 0}, {["y"] = 7, ["x"] = 15, ["name"] = "mcl_core:cobble", ["z"] = 32, ["meta"] = {["inventory"] = {}, ["fields"] = {}}, ["param2"] = 0, ["param1"] = 0}, {["y"] = 7, ["x"] = 15, ["name"] = "mcl_core:ladder", ["z"] = 35, ["meta"] = {["inventory"] = {}, ["fields"] = {}}, ["param2"] = 3, ["param1"] = 107}, {["y"] = 7, ["x"] = 15, ["name"] = "mcl_core:cobble", ["z"] = 36, ["meta"] = {["inventory"] = {}, ["fields"] = {}}, ["param2"] = 0, ["param1"] = 0}, {["y"] = 8, ["x"] = 15, ["name"] = "mcl_core:cobble", ["z"] = 32, ["meta"] = {["inventory"] = {}, ["fields"] = {}}, ["param2"] = 0, ["param1"] = 0}, {["y"] = 8, ["x"] = 15, ["name"] = "mcl_core:ladder", ["z"] = 35, ["meta"] = {["inventory"] = {}, ["fields"] = {}}, ["param2"] = 3, ["param1"] = 92}, {["y"] = 8, ["x"] = 15, ["name"] = "mcl_core:cobble", ["z"] = 36, ["meta"] = {["inventory"] = {}, ["fields"] = {}}, ["param2"] = 0, ["param1"] = 0}, {["y"] = 9, ["x"] = 15, ["name"] = "mcl_core:cobble", ["z"] = 32, ["meta"] = {["inventory"] = {}, ["fields"] = {}}, ["param2"] = 0, ["param1"] = 0}, {["y"] = 9, ["x"] = 15, ["name"] = "mcl_core:cobble", ["z"] = 33, ["meta"] = {["inventory"] = {}, ["fields"] = {}}, ["param2"] = 0, ["param1"] = 0}, {["y"] = 9, ["x"] = 15, ["name"] = "mcl_core:cobble", ["z"] = 34, ["meta"] = {["inventory"] = {}, ["fields"] = {}}, ["param2"] = 0, ["param1"] = 0}, {["y"] = 9, ["x"] = 15, ["name"] = "mcl_core:ladder", ["z"] = 35, ["meta"] = {["inventory"] = {}, ["fields"] = {}}, ["param2"] = 3, ["param1"] = 77}, {["y"] = 9, ["x"] = 15, ["name"] = "mcl_core:cobble", ["z"] = 36, ["meta"] = {["inventory"] = {}, ["fields"] = {}}, ["param2"] = 0, ["param1"] = 0}, {["y"] = 10, ["x"] = 15, ["name"] = "mcl_core:cobble", ["z"] = 32, ["meta"] = {["inventory"] = {}, ["fields"] = {}}, ["param2"] = 0, ["param1"] = 0}, {["y"] = 10, ["x"] = 15, ["name"] = "mcl_core:cobble", ["z"] = 36, ["meta"] = {["inventory"] = {}, ["fields"] = {}}, ["param2"] = 0, ["param1"] = 0}, {["y"] = 0, ["x"] = 16, ["name"] = "mcl_core:tree", ["z"] = 20, ["meta"] = {["inventory"] = {}, ["fields"] = {}}, ["param2"] = 0, ["param1"] = 0}, {["y"] = 0, ["x"] = 16, ["name"] = "mcl_core:tree", ["z"] = 21, ["meta"] = {["inventory"] = {}, ["fields"] = {}}, ["param2"] = 0, ["param1"] = 0}, {["y"] = 0, ["x"] = 16, ["name"] = "mcl_core:tree", ["z"] = 22, ["meta"] = {["inventory"] = {}, ["fields"] = {}}, ["param2"] = 0, ["param1"] = 0}, {["y"] = 0, ["x"] = 16, ["name"] = "mcl_core:tree", ["z"] = 23, ["meta"] = {["inventory"] = {}, ["fields"] = {}}, ["param2"] = 0, ["param1"] = 0}, {["y"] = 0, ["x"] = 16, ["name"] = "mcl_core:tree", ["z"] = 24, ["meta"] = {["inventory"] = {}, ["fields"] = {}}, ["param2"] = 0, ["param1"] = 0}, {["y"] = 0, ["x"] = 16, ["name"] = "mcl_core:tree", ["z"] = 25, ["meta"] = {["inventory"] = {}, ["fields"] = {}}, ["param2"] = 0, ["param1"] = 0}, {["y"] = 0, ["x"] = 16, ["name"] = "mcl_core:tree", ["z"] = 26, ["meta"] = {["inventory"] = {}, ["fields"] = {}}, ["param2"] = 0, ["param1"] = 0}, {["y"] = 0, ["x"] = 16, ["name"] = "mcl_core:tree", ["z"] = 27, ["meta"] = {["inventory"] = {}, ["fields"] = {}}, ["param2"] = 0, ["param1"] = 0}, {["y"] = 0, ["x"] = 16, ["name"] = "mcl_core:tree", ["z"] = 28, ["meta"] = {["inventory"] = {}, ["fields"] = {}}, ["param2"] = 3, ["param1"] = 0}, {["y"] = 0, ["x"] = 16, ["name"] = "stairs:stair_cobble", ["z"] = 31, ["meta"] = {["inventory"] = {}, ["fields"] = {}}, ["param2"] = 0, ["param1"] = 141}, {["y"] = 0, ["x"] = 16, ["name"] = "mcl_core:cobble", ["z"] = 32, ["meta"] = {["inventory"] = {}, ["fields"] = {}}, ["param2"] = 0, ["param1"] = 0}, {["y"] = 0, ["x"] = 16, ["name"] = "mcl_core:cobble", ["z"] = 33, ["meta"] = {["inventory"] = {}, ["fields"] = {}}, ["param2"] = 0, ["param1"] = 0}, {["y"] = 0, ["x"] = 16, ["name"] = "mcl_core:cobble", ["z"] = 34, ["meta"] = {["inventory"] = {}, ["fields"] = {}}, ["param2"] = 0, ["param1"] = 0}, {["y"] = 0, ["x"] = 16, ["name"] = "mcl_core:cobble", ["z"] = 35, ["meta"] = {["inventory"] = {}, ["fields"] = {}}, ["param2"] = 0, ["param1"] = 0}, {["y"] = 0, ["x"] = 16, ["name"] = "mcl_core:cobble", ["z"] = 36, ["meta"] = {["inventory"] = {}, ["fields"] = {}}, ["param2"] = 0, ["param1"] = 0}, {["y"] = 0, ["x"] = 16, ["name"] = "mcl_core:cobble", ["z"] = 37, ["meta"] = {["inventory"] = {}, ["fields"] = {}}, ["param2"] = 0, ["param1"] = 0}, {["y"] = 0, ["x"] = 16, ["name"] = "mcl_core:cobble", ["z"] = 38, ["meta"] = {["inventory"] = {}, ["fields"] = {}}, ["param2"] = 0, ["param1"] = 0}, {["y"] = 0, ["x"] = 16, ["name"] = "mcl_core:cobble", ["z"] = 39, ["meta"] = {["inventory"] = {}, ["fields"] = {}}, ["param2"] = 0, ["param1"] = 0}, {["y"] = 0, ["x"] = 16, ["name"] = "mcl_core:cobble", ["z"] = 40, ["meta"] = {["inventory"] = {}, ["fields"] = {}}, ["param2"] = 0, ["param1"] = 0}, {["y"] = 1, ["x"] = 16, ["name"] = "mcl_doors:wooden_door_b_1", ["z"] = 32, ["meta"] = {["inventory"] = {}, ["fields"] = {}}, ["param2"] = 0, ["param1"] = 173}, {["y"] = 1, ["x"] = 16, ["name"] = "stairs:stair_cobble", ["z"] = 38, ["meta"] = {["inventory"] = {}, ["fields"] = {}}, ["param2"] = 0, ["param1"] = 153}, {["y"] = 1, ["x"] = 16, ["name"] = "mcl_core:cobble", ["z"] = 39, ["meta"] = {["inventory"] = {}, ["fields"] = {}}, ["param2"] = 0, ["param1"] = 0}, {["y"] = 1, ["x"] = 16, ["name"] = "mcl_core:cobble", ["z"] = 40, ["meta"] = {["inventory"] = {}, ["fields"] = {}}, ["param2"] = 0, ["param1"] = 0}, {["y"] = 2, ["x"] = 16, ["name"] = "mcl_doors:wooden_door_t_1", ["z"] = 32, ["meta"] = {["inventory"] = {}, ["fields"] = {}}, ["param2"] = 0, ["param1"] = 189}, {["y"] = 2, ["x"] = 16, ["name"] = "mcl_core:cobble", ["z"] = 40, ["meta"] = {["inventory"] = {}, ["fields"] = {}}, ["param2"] = 0, ["param1"] = 0}, {["y"] = 3, ["x"] = 16, ["name"] = "mcl_core:cobble", ["z"] = 32, ["meta"] = {["inventory"] = {}, ["fields"] = {}}, ["param2"] = 0, ["param1"] = 0}, {["y"] = 3, ["x"] = 16, ["name"] = "mcl_torches:torch_wall", ["z"] = 33, ["meta"] = {["inventory"] = {}, ["fields"] = {}}, ["param2"] = 2, ["param1"] = 0}, {["y"] = 3, ["x"] = 16, ["name"] = "xpanes:pane_natural", ["z"] = 40, ["meta"] = {["inventory"] = {}, ["fields"] = {}}, ["param2"] = 0, ["param1"] = 189}, {["y"] = 4, ["x"] = 16, ["name"] = "mcl_core:cobble", ["z"] = 32, ["meta"] = {["inventory"] = {}, ["fields"] = {}}, ["param2"] = 0, ["param1"] = 0}, {["y"] = 4, ["x"] = 16, ["name"] = "mcl_core:cobble", ["z"] = 33, ["meta"] = {["inventory"] = {}, ["fields"] = {}}, ["param2"] = 0, ["param1"] = 0}, {["y"] = 4, ["x"] = 16, ["name"] = "mcl_core:cobble", ["z"] = 34, ["meta"] = {["inventory"] = {}, ["fields"] = {}}, ["param2"] = 0, ["param1"] = 0}, {["y"] = 4, ["x"] = 16, ["name"] = "mcl_core:cobble", ["z"] = 35, ["meta"] = {["inventory"] = {}, ["fields"] = {}}, ["param2"] = 0, ["param1"] = 0}, {["y"] = 4, ["x"] = 16, ["name"] = "mcl_core:cobble", ["z"] = 36, ["meta"] = {["inventory"] = {}, ["fields"] = {}}, ["param2"] = 0, ["param1"] = 0}, {["y"] = 4, ["x"] = 16, ["name"] = "mcl_torches:torch_wall", ["z"] = 39, ["meta"] = {["inventory"] = {}, ["fields"] = {}}, ["param2"] = 0, ["param1"] = 0}, {["y"] = 4, ["x"] = 16, ["name"] = "mcl_core:cobble", ["z"] = 40, ["meta"] = {["inventory"] = {}, ["fields"] = {}}, ["param2"] = 0, ["param1"] = 0}, {["y"] = 5, ["x"] = 16, ["name"] = "mcl_core:cobble", ["z"] = 32, ["meta"] = {["inventory"] = {}, ["fields"] = {}}, ["param2"] = 0, ["param1"] = 0}, {["y"] = 5, ["x"] = 16, ["name"] = "mcl_core:cobble", ["z"] = 36, ["meta"] = {["inventory"] = {}, ["fields"] = {}}, ["param2"] = 0, ["param1"] = 0}, {["y"] = 5, ["x"] = 16, ["name"] = "mcl_core:cobble", ["z"] = 37, ["meta"] = {["inventory"] = {}, ["fields"] = {}}, ["param2"] = 0, ["param1"] = 0}, {["y"] = 5, ["x"] = 16, ["name"] = "mcl_core:cobble", ["z"] = 38, ["meta"] = {["inventory"] = {}, ["fields"] = {}}, ["param2"] = 0, ["param1"] = 0}, {["y"] = 5, ["x"] = 16, ["name"] = "mcl_core:cobble", ["z"] = 39, ["meta"] = {["inventory"] = {}, ["fields"] = {}}, ["param2"] = 0, ["param1"] = 0}, {["y"] = 6, ["x"] = 16, ["name"] = "xpanes:pane_natural", ["z"] = 32, ["meta"] = {["inventory"] = {}, ["fields"] = {}}, ["param2"] = 0, ["param1"] = 93}, {["y"] = 6, ["x"] = 16, ["name"] = "xpanes:pane_natural", ["z"] = 36, ["meta"] = {["inventory"] = {}, ["fields"] = {}}, ["param2"] = 0, ["param1"] = 93}, {["y"] = 7, ["x"] = 16, ["name"] = "xpanes:pane_natural", ["z"] = 32, ["meta"] = {["inventory"] = {}, ["fields"] = {}}, ["param2"] = 0, ["param1"] = 77}, {["y"] = 7, ["x"] = 16, ["name"] = "xpanes:pane_natural", ["z"] = 36, ["meta"] = {["inventory"] = {}, ["fields"] = {}}, ["param2"] = 0, ["param1"] = 77}, {["y"] = 8, ["x"] = 16, ["name"] = "mcl_core:cobble", ["z"] = 32, ["meta"] = {["inventory"] = {}, ["fields"] = {}}, ["param2"] = 0, ["param1"] = 0}, {["y"] = 8, ["x"] = 16, ["name"] = "mcl_core:cobble", ["z"] = 36, ["meta"] = {["inventory"] = {}, ["fields"] = {}}, ["param2"] = 0, ["param1"] = 0}, {["y"] = 9, ["x"] = 16, ["name"] = "mcl_core:cobble", ["z"] = 32, ["meta"] = {["inventory"] = {}, ["fields"] = {}}, ["param2"] = 0, ["param1"] = 0}, {["y"] = 9, ["x"] = 16, ["name"] = "mcl_core:cobble", ["z"] = 33, ["meta"] = {["inventory"] = {}, ["fields"] = {}}, ["param2"] = 0, ["param1"] = 0}, {["y"] = 9, ["x"] = 16, ["name"] = "mcl_core:cobble", ["z"] = 34, ["meta"] = {["inventory"] = {}, ["fields"] = {}}, ["param2"] = 0, ["param1"] = 0}, {["y"] = 9, ["x"] = 16, ["name"] = "mcl_core:cobble", ["z"] = 35, ["meta"] = {["inventory"] = {}, ["fields"] = {}}, ["param2"] = 0, ["param1"] = 0}, {["y"] = 9, ["x"] = 16, ["name"] = "mcl_core:cobble", ["z"] = 36, ["meta"] = {["inventory"] = {}, ["fields"] = {}}, ["param2"] = 0, ["param1"] = 0}, {["y"] = 10, ["x"] = 16, ["name"] = "mcl_core:cobble", ["z"] = 32, ["meta"] = {["inventory"] = {}, ["fields"] = {}}, ["param2"] = 0, ["param1"] = 0}, {["y"] = 10, ["x"] = 16, ["name"] = "mcl_core:cobble", ["z"] = 36, ["meta"] = {["inventory"] = {}, ["fields"] = {}}, ["param2"] = 0, ["param1"] = 0}, {["y"] = 11, ["x"] = 16, ["name"] = "mcl_core:cobble", ["z"] = 32, ["meta"] = {["inventory"] = {}, ["fields"] = {}}, ["param2"] = 0, ["param1"] = 0}, {["y"] = 11, ["x"] = 16, ["name"] = "mcl_core:cobble", ["z"] = 36, ["meta"] = {["inventory"] = {}, ["fields"] = {}}, ["param2"] = 0, ["param1"] = 0}, {["y"] = 0, ["x"] = 17, ["name"] = "mcl_core:cobble", ["z"] = 32, ["meta"] = {["inventory"] = {}, ["fields"] = {}}, ["param2"] = 0, ["param1"] = 0}, {["y"] = 0, ["x"] = 17, ["name"] = "mcl_core:cobble", ["z"] = 33, ["meta"] = {["inventory"] = {}, ["fields"] = {}}, ["param2"] = 0, ["param1"] = 0}, {["y"] = 0, ["x"] = 17, ["name"] = "mcl_core:cobble", ["z"] = 34, ["meta"] = {["inventory"] = {}, ["fields"] = {}}, ["param2"] = 0, ["param1"] = 0}, {["y"] = 0, ["x"] = 17, ["name"] = "mcl_core:cobble", ["z"] = 35, ["meta"] = {["inventory"] = {}, ["fields"] = {}}, ["param2"] = 0, ["param1"] = 0}, {["y"] = 0, ["x"] = 17, ["name"] = "mcl_core:cobble", ["z"] = 36, ["meta"] = {["inventory"] = {}, ["fields"] = {}}, ["param2"] = 0, ["param1"] = 0}, {["y"] = 0, ["x"] = 17, ["name"] = "mcl_core:cobble", ["z"] = 37, ["meta"] = {["inventory"] = {}, ["fields"] = {}}, ["param2"] = 0, ["param1"] = 0}, {["y"] = 0, ["x"] = 17, ["name"] = "mcl_core:cobble", ["z"] = 38, ["meta"] = {["inventory"] = {}, ["fields"] = {}}, ["param2"] = 0, ["param1"] = 0}, {["y"] = 0, ["x"] = 17, ["name"] = "mcl_core:cobble", ["z"] = 39, ["meta"] = {["inventory"] = {}, ["fields"] = {}}, ["param2"] = 0, ["param1"] = 0}, {["y"] = 0, ["x"] = 17, ["name"] = "mcl_core:cobble", ["z"] = 40, ["meta"] = {["inventory"] = {}, ["fields"] = {}}, ["param2"] = 0, ["param1"] = 0}, {["y"] = 1, ["x"] = 17, ["name"] = "mcl_core:cobble", ["z"] = 32, ["meta"] = {["inventory"] = {}, ["fields"] = {}}, ["param2"] = 0, ["param1"] = 0}, {["y"] = 1, ["x"] = 17, ["name"] = "stairs:stair_cobble", ["z"] = 37, ["meta"] = {["inventory"] = {}, ["fields"] = {}}, ["param2"] = 0, ["param1"] = 121}, {["y"] = 1, ["x"] = 17, ["name"] = "mcl_core:cobble", ["z"] = 38, ["meta"] = {["inventory"] = {}, ["fields"] = {}}, ["param2"] = 0, ["param1"] = 0}, {["y"] = 1, ["x"] = 17, ["name"] = "mcl_core:cobble", ["z"] = 39, ["meta"] = {["inventory"] = {}, ["fields"] = {}}, ["param2"] = 0, ["param1"] = 0}, {["y"] = 1, ["x"] = 17, ["name"] = "mcl_core:cobble", ["z"] = 40, ["meta"] = {["inventory"] = {}, ["fields"] = {}}, ["param2"] = 0, ["param1"] = 0}, {["y"] = 2, ["x"] = 17, ["name"] = "mcl_core:cobble", ["z"] = 32, ["meta"] = {["inventory"] = {}, ["fields"] = {}}, ["param2"] = 0, ["param1"] = 0}, {["y"] = 2, ["x"] = 17, ["name"] = "stairs:stair_cobble", ["z"] = 39, ["meta"] = {["inventory"] = {}, ["fields"] = {}}, ["param2"] = 0, ["param1"] = 170}, {["y"] = 2, ["x"] = 17, ["name"] = "mcl_core:cobble", ["z"] = 40, ["meta"] = {["inventory"] = {}, ["fields"] = {}}, ["param2"] = 0, ["param1"] = 0}, {["y"] = 3, ["x"] = 17, ["name"] = "mcl_torches:torch_wall", ["z"] = 28, ["meta"] = {["inventory"] = {}, ["fields"] = {}}, ["param2"] = 1, ["param1"] = 15}, {["y"] = 3, ["x"] = 17, ["name"] = "mcl_core:cobble", ["z"] = 32, ["meta"] = {["inventory"] = {}, ["fields"] = {}}, ["param2"] = 0, ["param1"] = 0}, {["y"] = 3, ["x"] = 17, ["name"] = "mcl_core:cobble", ["z"] = 40, ["meta"] = {["inventory"] = {}, ["fields"] = {}}, ["param2"] = 0, ["param1"] = 0}, {["y"] = 4, ["x"] = 17, ["name"] = "mcl_core:cobble", ["z"] = 32, ["meta"] = {["inventory"] = {}, ["fields"] = {}}, ["param2"] = 0, ["param1"] = 0}, {["y"] = 4, ["x"] = 17, ["name"] = "mcl_core:cobble", ["z"] = 33, ["meta"] = {["inventory"] = {}, ["fields"] = {}}, ["param2"] = 0, ["param1"] = 0}, {["y"] = 4, ["x"] = 17, ["name"] = "mcl_core:cobble", ["z"] = 34, ["meta"] = {["inventory"] = {}, ["fields"] = {}}, ["param2"] = 0, ["param1"] = 0}, {["y"] = 4, ["x"] = 17, ["name"] = "mcl_core:cobble", ["z"] = 35, ["meta"] = {["inventory"] = {}, ["fields"] = {}}, ["param2"] = 0, ["param1"] = 0}, {["y"] = 4, ["x"] = 17, ["name"] = "mcl_core:cobble", ["z"] = 36, ["meta"] = {["inventory"] = {}, ["fields"] = {}}, ["param2"] = 0, ["param1"] = 0}, {["y"] = 4, ["x"] = 17, ["name"] = "mcl_core:cobble", ["z"] = 40, ["meta"] = {["inventory"] = {}, ["fields"] = {}}, ["param2"] = 0, ["param1"] = 0}, {["y"] = 5, ["x"] = 17, ["name"] = "mcl_core:cobble", ["z"] = 32, ["meta"] = {["inventory"] = {}, ["fields"] = {}}, ["param2"] = 0, ["param1"] = 0}, {["y"] = 5, ["x"] = 17, ["name"] = "mcl_core:cobble", ["z"] = 36, ["meta"] = {["inventory"] = {}, ["fields"] = {}}, ["param2"] = 0, ["param1"] = 0}, {["y"] = 5, ["x"] = 17, ["name"] = "mcl_core:cobble", ["z"] = 37, ["meta"] = {["inventory"] = {}, ["fields"] = {}}, ["param2"] = 0, ["param1"] = 0}, {["y"] = 5, ["x"] = 17, ["name"] = "mcl_core:cobble", ["z"] = 38, ["meta"] = {["inventory"] = {}, ["fields"] = {}}, ["param2"] = 0, ["param1"] = 0}, {["y"] = 5, ["x"] = 17, ["name"] = "mcl_core:cobble", ["z"] = 39, ["meta"] = {["inventory"] = {}, ["fields"] = {}}, ["param2"] = 0, ["param1"] = 0}, {["y"] = 6, ["x"] = 17, ["name"] = "mcl_core:cobble", ["z"] = 32, ["meta"] = {["inventory"] = {}, ["fields"] = {}}, ["param2"] = 0, ["param1"] = 0}, {["y"] = 6, ["x"] = 17, ["name"] = "mcl_core:cobble", ["z"] = 36, ["meta"] = {["inventory"] = {}, ["fields"] = {}}, ["param2"] = 0, ["param1"] = 0}, {["y"] = 7, ["x"] = 17, ["name"] = "mcl_core:cobble", ["z"] = 32, ["meta"] = {["inventory"] = {}, ["fields"] = {}}, ["param2"] = 0, ["param1"] = 0}, {["y"] = 7, ["x"] = 17, ["name"] = "mcl_core:cobble", ["z"] = 36, ["meta"] = {["inventory"] = {}, ["fields"] = {}}, ["param2"] = 0, ["param1"] = 0}, {["y"] = 8, ["x"] = 17, ["name"] = "mcl_core:cobble", ["z"] = 32, ["meta"] = {["inventory"] = {}, ["fields"] = {}}, ["param2"] = 0, ["param1"] = 0}, {["y"] = 8, ["x"] = 17, ["name"] = "mcl_core:cobble", ["z"] = 36, ["meta"] = {["inventory"] = {}, ["fields"] = {}}, ["param2"] = 0, ["param1"] = 0}, {["y"] = 9, ["x"] = 17, ["name"] = "mcl_core:cobble", ["z"] = 32, ["meta"] = {["inventory"] = {}, ["fields"] = {}}, ["param2"] = 0, ["param1"] = 0}, {["y"] = 9, ["x"] = 17, ["name"] = "mcl_core:cobble", ["z"] = 33, ["meta"] = {["inventory"] = {}, ["fields"] = {}}, ["param2"] = 0, ["param1"] = 0}, {["y"] = 9, ["x"] = 17, ["name"] = "mcl_core:cobble", ["z"] = 34, ["meta"] = {["inventory"] = {}, ["fields"] = {}}, ["param2"] = 0, ["param1"] = 0}, {["y"] = 9, ["x"] = 17, ["name"] = "mcl_core:cobble", ["z"] = 35, ["meta"] = {["inventory"] = {}, ["fields"] = {}}, ["param2"] = 0, ["param1"] = 0}, {["y"] = 9, ["x"] = 17, ["name"] = "mcl_core:cobble", ["z"] = 36, ["meta"] = {["inventory"] = {}, ["fields"] = {}}, ["param2"] = 0, ["param1"] = 0}, {["y"] = 10, ["x"] = 17, ["name"] = "mcl_core:cobble", ["z"] = 32, ["meta"] = {["inventory"] = {}, ["fields"] = {}}, ["param2"] = 0, ["param1"] = 0}, {["y"] = 10, ["x"] = 17, ["name"] = "mcl_core:cobble", ["z"] = 36, ["meta"] = {["inventory"] = {}, ["fields"] = {}}, ["param2"] = 0, ["param1"] = 0}, {["y"] = 0, ["x"] = 18, ["name"] = "mcl_fences:fence", ["z"] = 28, ["meta"] = {["inventory"] = {}, ["fields"] = {}}, ["param2"] = 0, ["param1"] = 156}, {["y"] = 0, ["x"] = 18, ["name"] = "mcl_core:cobble", ["z"] = 36, ["meta"] = {["inventory"] = {}, ["fields"] = {}}, ["param2"] = 0, ["param1"] = 0}, {["y"] = 0, ["x"] = 18, ["name"] = "mcl_core:cobble", ["z"] = 37, ["meta"] = {["inventory"] = {}, ["fields"] = {}}, ["param2"] = 0, ["param1"] = 0}, {["y"] = 0, ["x"] = 18, ["name"] = "mcl_core:cobble", ["z"] = 38, ["meta"] = {["inventory"] = {}, ["fields"] = {}}, ["param2"] = 0, ["param1"] = 0}, {["y"] = 0, ["x"] = 18, ["name"] = "mcl_core:cobble", ["z"] = 39, ["meta"] = {["inventory"] = {}, ["fields"] = {}}, ["param2"] = 0, ["param1"] = 0}, {["y"] = 0, ["x"] = 18, ["name"] = "mcl_core:cobble", ["z"] = 46, ["meta"] = {["inventory"] = {}, ["fields"] = {}}, ["param2"] = 0, ["param1"] = 0}, {["y"] = 0, ["x"] = 18, ["name"] = "mcl_core:cobble", ["z"] = 47, ["meta"] = {["inventory"] = {}, ["fields"] = {}}, ["param2"] = 0, ["param1"] = 0}, {["y"] = 0, ["x"] = 18, ["name"] = "mcl_core:cobble", ["z"] = 48, ["meta"] = {["inventory"] = {}, ["fields"] = {}}, ["param2"] = 0, ["param1"] = 0}, {["y"] = 0, ["x"] = 18, ["name"] = "mcl_core:cobble", ["z"] = 49, ["meta"] = {["inventory"] = {}, ["fields"] = {}}, ["param2"] = 0, ["param1"] = 0}, {["y"] = 0, ["x"] = 18, ["name"] = "mcl_core:cobble", ["z"] = 50, ["meta"] = {["inventory"] = {}, ["fields"] = {}}, ["param2"] = 0, ["param1"] = 0}, {["y"] = 1, ["x"] = 18, ["name"] = "mcl_fences:fence", ["z"] = 28, ["meta"] = {["inventory"] = {}, ["fields"] = {}}, ["param2"] = 0, ["param1"] = 173}, {["y"] = 1, ["x"] = 18, ["name"] = "mcl_core:cobble", ["z"] = 33, ["meta"] = {["inventory"] = {}, ["fields"] = {}}, ["param2"] = 0, ["param1"] = 0}, {["y"] = 1, ["x"] = 18, ["name"] = "mcl_core:cobble", ["z"] = 34, ["meta"] = {["inventory"] = {}, ["fields"] = {}}, ["param2"] = 0, ["param1"] = 0}, {["y"] = 1, ["x"] = 18, ["name"] = "mcl_core:cobble", ["z"] = 35, ["meta"] = {["inventory"] = {}, ["fields"] = {}}, ["param2"] = 0, ["param1"] = 0}, {["y"] = 1, ["x"] = 18, ["name"] = "mcl_core:cobble", ["z"] = 36, ["meta"] = {["inventory"] = {}, ["fields"] = {}}, ["param2"] = 0, ["param1"] = 0}, {["y"] = 1, ["x"] = 18, ["name"] = "mcl_core:cobble", ["z"] = 37, ["meta"] = {["inventory"] = {}, ["fields"] = {}}, ["param2"] = 0, ["param1"] = 0}, {["y"] = 1, ["x"] = 18, ["name"] = "mcl_core:cobble", ["z"] = 38, ["meta"] = {["inventory"] = {}, ["fields"] = {}}, ["param2"] = 0, ["param1"] = 0}, {["y"] = 1, ["x"] = 18, ["name"] = "mcl_core:cobble", ["z"] = 39, ["meta"] = {["inventory"] = {}, ["fields"] = {}}, ["param2"] = 0, ["param1"] = 0}, {["y"] = 1, ["x"] = 18, ["name"] = "mcl_core:cobble", ["z"] = 46, ["meta"] = {["inventory"] = {}, ["fields"] = {}}, ["param2"] = 0, ["param1"] = 0}, {["y"] = 1, ["x"] = 18, ["name"] = "mcl_core:wood", ["z"] = 47, ["meta"] = {["inventory"] = {}, ["fields"] = {}}, ["param2"] = 0, ["param1"] = 0}, {["y"] = 1, ["x"] = 18, ["name"] = "mcl_core:wood", ["z"] = 48, ["meta"] = {["inventory"] = {}, ["fields"] = {}}, ["param2"] = 0, ["param1"] = 0}, {["y"] = 1, ["x"] = 18, ["name"] = "mcl_core:wood", ["z"] = 49, ["meta"] = {["inventory"] = {}, ["fields"] = {}}, ["param2"] = 0, ["param1"] = 0}, {["y"] = 1, ["x"] = 18, ["name"] = "mcl_core:cobble", ["z"] = 50, ["meta"] = {["inventory"] = {}, ["fields"] = {}}, ["param2"] = 0, ["param1"] = 0}, {["y"] = 2, ["x"] = 18, ["name"] = "mcl_fences:fence", ["z"] = 28, ["meta"] = {["inventory"] = {}, ["fields"] = {}}, ["param2"] = 0, ["param1"] = 189}, {["y"] = 2, ["x"] = 18, ["name"] = "mcl_core:cobble", ["z"] = 33, ["meta"] = {["inventory"] = {}, ["fields"] = {}}, ["param2"] = 0, ["param1"] = 0}, {["y"] = 2, ["x"] = 18, ["name"] = "xpanes:pane_natural", ["z"] = 34, ["meta"] = {["inventory"] = {}, ["fields"] = {}}, ["param2"] = 0, ["param1"] = 157}, {["y"] = 2, ["x"] = 18, ["name"] = "mcl_core:cobble", ["z"] = 35, ["meta"] = {["inventory"] = {}, ["fields"] = {}}, ["param2"] = 0, ["param1"] = 0}, {["y"] = 2, ["x"] = 18, ["name"] = "mcl_core:cobble", ["z"] = 36, ["meta"] = {["inventory"] = {}, ["fields"] = {}}, ["param2"] = 0, ["param1"] = 0}, {["y"] = 2, ["x"] = 18, ["name"] = "mcl_core:cobble", ["z"] = 37, ["meta"] = {["inventory"] = {}, ["fields"] = {}}, ["param2"] = 0, ["param1"] = 0}, {["y"] = 2, ["x"] = 18, ["name"] = "mcl_core:cobble", ["z"] = 38, ["meta"] = {["inventory"] = {}, ["fields"] = {}}, ["param2"] = 0, ["param1"] = 0}, {["y"] = 2, ["x"] = 18, ["name"] = "mcl_core:cobble", ["z"] = 39, ["meta"] = {["inventory"] = {}, ["fields"] = {}}, ["param2"] = 0, ["param1"] = 0}, {["y"] = 2, ["x"] = 18, ["name"] = "mcl_core:cobble", ["z"] = 46, ["meta"] = {["inventory"] = {}, ["fields"] = {}}, ["param2"] = 0, ["param1"] = 0}, {["y"] = 2, ["x"] = 18, ["name"] = "mcl_core:wood", ["z"] = 47, ["meta"] = {["inventory"] = {}, ["fields"] = {}}, ["param2"] = 0, ["param1"] = 0}, {["y"] = 2, ["x"] = 18, ["name"] = "xpanes:pane_natural", ["z"] = 48, ["meta"] = {["inventory"] = {}, ["fields"] = {}}, ["param2"] = 0, ["param1"] = 157}, {["y"] = 2, ["x"] = 18, ["name"] = "mcl_core:wood", ["z"] = 49, ["meta"] = {["inventory"] = {}, ["fields"] = {}}, ["param2"] = 0, ["param1"] = 0}, {["y"] = 2, ["x"] = 18, ["name"] = "mcl_core:cobble", ["z"] = 50, ["meta"] = {["inventory"] = {}, ["fields"] = {}}, ["param2"] = 0, ["param1"] = 0}, {["y"] = 3, ["x"] = 18, ["name"] = "mcl_torches:torch_wall", ["z"] = 27, ["meta"] = {["inventory"] = {}, ["fields"] = {}}, ["param2"] = 0, ["param1"] = 15}, {["y"] = 3, ["x"] = 18, ["name"] = "mcl_wool:black", ["z"] = 28, ["meta"] = {["inventory"] = {}, ["fields"] = {}}, ["param2"] = 0, ["param1"] = 0}, {["y"] = 3, ["x"] = 18, ["name"] = "mcl_torches:torch_wall", ["z"] = 29, ["meta"] = {["inventory"] = {}, ["fields"] = {}}, ["param2"] = 2, ["param1"] = 15}, {["y"] = 3, ["x"] = 18, ["name"] = "mcl_core:cobble", ["z"] = 33, ["meta"] = {["inventory"] = {}, ["fields"] = {}}, ["param2"] = 0, ["param1"] = 0}, {["y"] = 3, ["x"] = 18, ["name"] = "xpanes:pane_natural", ["z"] = 34, ["meta"] = {["inventory"] = {}, ["fields"] = {}}, ["param2"] = 0, ["param1"] = 173}, {["y"] = 3, ["x"] = 18, ["name"] = "mcl_core:cobble", ["z"] = 35, ["meta"] = {["inventory"] = {}, ["fields"] = {}}, ["param2"] = 0, ["param1"] = 0}, {["y"] = 3, ["x"] = 18, ["name"] = "mcl_core:cobble", ["z"] = 36, ["meta"] = {["inventory"] = {}, ["fields"] = {}}, ["param2"] = 0, ["param1"] = 0}, {["y"] = 3, ["x"] = 18, ["name"] = "mcl_core:cobble", ["z"] = 37, ["meta"] = {["inventory"] = {}, ["fields"] = {}}, ["param2"] = 0, ["param1"] = 0}, {["y"] = 3, ["x"] = 18, ["name"] = "xpanes:pane_natural", ["z"] = 38, ["meta"] = {["inventory"] = {}, ["fields"] = {}}, ["param2"] = 0, ["param1"] = 157}, {["y"] = 3, ["x"] = 18, ["name"] = "mcl_core:cobble", ["z"] = 39, ["meta"] = {["inventory"] = {}, ["fields"] = {}}, ["param2"] = 0, ["param1"] = 0}, {["y"] = 3, ["x"] = 18, ["name"] = "mcl_core:cobble", ["z"] = 46, ["meta"] = {["inventory"] = {}, ["fields"] = {}}, ["param2"] = 0, ["param1"] = 0}, {["y"] = 3, ["x"] = 18, ["name"] = "mcl_core:wood", ["z"] = 47, ["meta"] = {["inventory"] = {}, ["fields"] = {}}, ["param2"] = 0, ["param1"] = 0}, {["y"] = 3, ["x"] = 18, ["name"] = "mcl_core:wood", ["z"] = 48, ["meta"] = {["inventory"] = {}, ["fields"] = {}}, ["param2"] = 0, ["param1"] = 0}, {["y"] = 3, ["x"] = 18, ["name"] = "mcl_core:wood", ["z"] = 49, ["meta"] = {["inventory"] = {}, ["fields"] = {}}, ["param2"] = 0, ["param1"] = 0}, {["y"] = 3, ["x"] = 18, ["name"] = "mcl_core:cobble", ["z"] = 50, ["meta"] = {["inventory"] = {}, ["fields"] = {}}, ["param2"] = 0, ["param1"] = 0}, {["y"] = 4, ["x"] = 18, ["name"] = "mcl_core:cobble", ["z"] = 32, ["meta"] = {["inventory"] = {}, ["fields"] = {}}, ["param2"] = 0, ["param1"] = 0}, {["y"] = 4, ["x"] = 18, ["name"] = "mcl_core:cobble", ["z"] = 33, ["meta"] = {["inventory"] = {}, ["fields"] = {}}, ["param2"] = 0, ["param1"] = 0}, {["y"] = 4, ["x"] = 18, ["name"] = "mcl_core:cobble", ["z"] = 34, ["meta"] = {["inventory"] = {}, ["fields"] = {}}, ["param2"] = 0, ["param1"] = 0}, {["y"] = 4, ["x"] = 18, ["name"] = "mcl_core:cobble", ["z"] = 35, ["meta"] = {["inventory"] = {}, ["fields"] = {}}, ["param2"] = 0, ["param1"] = 0}, {["y"] = 4, ["x"] = 18, ["name"] = "mcl_core:cobble", ["z"] = 36, ["meta"] = {["inventory"] = {}, ["fields"] = {}}, ["param2"] = 0, ["param1"] = 0}, {["y"] = 4, ["x"] = 18, ["name"] = "mcl_core:cobble", ["z"] = 37, ["meta"] = {["inventory"] = {}, ["fields"] = {}}, ["param2"] = 0, ["param1"] = 0}, {["y"] = 4, ["x"] = 18, ["name"] = "mcl_core:cobble", ["z"] = 38, ["meta"] = {["inventory"] = {}, ["fields"] = {}}, ["param2"] = 0, ["param1"] = 0}, {["y"] = 4, ["x"] = 18, ["name"] = "mcl_core:cobble", ["z"] = 39, ["meta"] = {["inventory"] = {}, ["fields"] = {}}, ["param2"] = 0, ["param1"] = 0}, {["y"] = 4, ["x"] = 18, ["name"] = "mcl_core:tree", ["z"] = 46, ["meta"] = {["inventory"] = {}, ["fields"] = {}}, ["param2"] = 3, ["param1"] = 0}, {["y"] = 4, ["x"] = 18, ["name"] = "mcl_core:tree", ["z"] = 47, ["meta"] = {["inventory"] = {}, ["fields"] = {}}, ["param2"] = 0, ["param1"] = 0}, {["y"] = 4, ["x"] = 18, ["name"] = "mcl_core:tree", ["z"] = 48, ["meta"] = {["inventory"] = {}, ["fields"] = {}}, ["param2"] = 0, ["param1"] = 0}, {["y"] = 4, ["x"] = 18, ["name"] = "mcl_core:tree", ["z"] = 49, ["meta"] = {["inventory"] = {}, ["fields"] = {}}, ["param2"] = 0, ["param1"] = 0}, {["y"] = 4, ["x"] = 18, ["name"] = "mcl_core:tree", ["z"] = 50, ["meta"] = {["inventory"] = {}, ["fields"] = {}}, ["param2"] = 1, ["param1"] = 0}, {["y"] = 5, ["x"] = 18, ["name"] = "mcl_core:cobble", ["z"] = 33, ["meta"] = {["inventory"] = {}, ["fields"] = {}}, ["param2"] = 0, ["param1"] = 0}, {["y"] = 5, ["x"] = 18, ["name"] = "mcl_core:cobble", ["z"] = 34, ["meta"] = {["inventory"] = {}, ["fields"] = {}}, ["param2"] = 0, ["param1"] = 0}, {["y"] = 5, ["x"] = 18, ["name"] = "mcl_core:cobble", ["z"] = 35, ["meta"] = {["inventory"] = {}, ["fields"] = {}}, ["param2"] = 0, ["param1"] = 0}, {["y"] = 6, ["x"] = 18, ["name"] = "mcl_core:cobble", ["z"] = 33, ["meta"] = {["inventory"] = {}, ["fields"] = {}}, ["param2"] = 0, ["param1"] = 0}, {["y"] = 6, ["x"] = 18, ["name"] = "xpanes:pane_natural", ["z"] = 34, ["meta"] = {["inventory"] = {}, ["fields"] = {}}, ["param2"] = 0, ["param1"] = 93}, {["y"] = 6, ["x"] = 18, ["name"] = "mcl_core:cobble", ["z"] = 35, ["meta"] = {["inventory"] = {}, ["fields"] = {}}, ["param2"] = 0, ["param1"] = 0}, {["y"] = 7, ["x"] = 18, ["name"] = "mcl_core:cobble", ["z"] = 33, ["meta"] = {["inventory"] = {}, ["fields"] = {}}, ["param2"] = 0, ["param1"] = 0}, {["y"] = 7, ["x"] = 18, ["name"] = "xpanes:pane_natural", ["z"] = 34, ["meta"] = {["inventory"] = {}, ["fields"] = {}}, ["param2"] = 0, ["param1"] = 77}, {["y"] = 7, ["x"] = 18, ["name"] = "mcl_core:cobble", ["z"] = 35, ["meta"] = {["inventory"] = {}, ["fields"] = {}}, ["param2"] = 0, ["param1"] = 0}, {["y"] = 8, ["x"] = 18, ["name"] = "mcl_core:cobble", ["z"] = 33, ["meta"] = {["inventory"] = {}, ["fields"] = {}}, ["param2"] = 0, ["param1"] = 0}, {["y"] = 8, ["x"] = 18, ["name"] = "mcl_core:cobble", ["z"] = 34, ["meta"] = {["inventory"] = {}, ["fields"] = {}}, ["param2"] = 0, ["param1"] = 0}, {["y"] = 8, ["x"] = 18, ["name"] = "mcl_core:cobble", ["z"] = 35, ["meta"] = {["inventory"] = {}, ["fields"] = {}}, ["param2"] = 0, ["param1"] = 0}, {["y"] = 9, ["x"] = 18, ["name"] = "mcl_core:cobble", ["z"] = 32, ["meta"] = {["inventory"] = {}, ["fields"] = {}}, ["param2"] = 0, ["param1"] = 0}, {["y"] = 9, ["x"] = 18, ["name"] = "mcl_core:cobble", ["z"] = 33, ["meta"] = {["inventory"] = {}, ["fields"] = {}}, ["param2"] = 0, ["param1"] = 0}, {["y"] = 9, ["x"] = 18, ["name"] = "mcl_core:cobble", ["z"] = 34, ["meta"] = {["inventory"] = {}, ["fields"] = {}}, ["param2"] = 0, ["param1"] = 0}, {["y"] = 9, ["x"] = 18, ["name"] = "mcl_core:cobble", ["z"] = 35, ["meta"] = {["inventory"] = {}, ["fields"] = {}}, ["param2"] = 0, ["param1"] = 0}, {["y"] = 9, ["x"] = 18, ["name"] = "mcl_core:cobble", ["z"] = 36, ["meta"] = {["inventory"] = {}, ["fields"] = {}}, ["param2"] = 0, ["param1"] = 0}, {["y"] = 10, ["x"] = 18, ["name"] = "mcl_core:cobble", ["z"] = 33, ["meta"] = {["inventory"] = {}, ["fields"] = {}}, ["param2"] = 0, ["param1"] = 0}, {["y"] = 10, ["x"] = 18, ["name"] = "mcl_core:cobble", ["z"] = 34, ["meta"] = {["inventory"] = {}, ["fields"] = {}}, ["param2"] = 0, ["param1"] = 0}, {["y"] = 10, ["x"] = 18, ["name"] = "mcl_core:cobble", ["z"] = 35, ["meta"] = {["inventory"] = {}, ["fields"] = {}}, ["param2"] = 0, ["param1"] = 0}, {["y"] = 11, ["x"] = 18, ["name"] = "mcl_core:cobble", ["z"] = 34, ["meta"] = {["inventory"] = {}, ["fields"] = {}}, ["param2"] = 0, ["param1"] = 0}, {["y"] = 0, ["x"] = 19, ["name"] = "mcl_core:cobble", ["z"] = 46, ["meta"] = {["inventory"] = {}, ["fields"] = {}}, ["param2"] = 0, ["param1"] = 0}, {["y"] = 0, ["x"] = 19, ["name"] = "mcl_core:dirt", ["z"] = 47, ["meta"] = {["inventory"] = {}, ["fields"] = {}}, ["param2"] = 0, ["param1"] = 0}, {["y"] = 0, ["x"] = 19, ["name"] = "mcl_core:dirt", ["z"] = 48, ["meta"] = {["inventory"] = {}, ["fields"] = {}}, ["param2"] = 0, ["param1"] = 0}, {["y"] = 0, ["x"] = 19, ["name"] = "mcl_core:dirt", ["z"] = 49, ["meta"] = {["inventory"] = {}, ["fields"] = {}}, ["param2"] = 0, ["param1"] = 0}, {["y"] = 0, ["x"] = 19, ["name"] = "mcl_core:cobble", ["z"] = 50, ["meta"] = {["inventory"] = {}, ["fields"] = {}}, ["param2"] = 0, ["param1"] = 0}, {["y"] = 1, ["x"] = 19, ["name"] = "mcl_core:wood", ["z"] = 46, ["meta"] = {["inventory"] = {}, ["fields"] = {}}, ["param2"] = 0, ["param1"] = 0}, {["y"] = 1, ["x"] = 19, ["name"] = "mcl_core:wood", ["z"] = 50, ["meta"] = {["inventory"] = {}, ["fields"] = {}}, ["param2"] = 0, ["param1"] = 0}, {["y"] = 2, ["x"] = 19, ["name"] = "mcl_core:wood", ["z"] = 46, ["meta"] = {["inventory"] = {}, ["fields"] = {}}, ["param2"] = 0, ["param1"] = 0}, {["y"] = 2, ["x"] = 19, ["name"] = "mcl_core:wood", ["z"] = 50, ["meta"] = {["inventory"] = {}, ["fields"] = {}}, ["param2"] = 0, ["param1"] = 0}, {["y"] = 3, ["x"] = 19, ["name"] = "mcl_torches:torch_wall", ["z"] = 28, ["meta"] = {["inventory"] = {}, ["fields"] = {}}, ["param2"] = 3, ["param1"] = 15}, {["y"] = 3, ["x"] = 19, ["name"] = "mcl_core:wood", ["z"] = 46, ["meta"] = {["inventory"] = {}, ["fields"] = {}}, ["param2"] = 0, ["param1"] = 0}, {["y"] = 3, ["x"] = 19, ["name"] = "mcl_core:wood", ["z"] = 50, ["meta"] = {["inventory"] = {}, ["fields"] = {}}, ["param2"] = 0, ["param1"] = 0}, {["y"] = 4, ["x"] = 19, ["name"] = "mcl_core:tree", ["z"] = 46, ["meta"] = {["inventory"] = {}, ["fields"] = {}}, ["param2"] = 3, ["param1"] = 0}, {["y"] = 4, ["x"] = 19, ["name"] = "mcl_core:wood", ["z"] = 47, ["meta"] = {["inventory"] = {}, ["fields"] = {}}, ["param2"] = 0, ["param1"] = 0}, {["y"] = 4, ["x"] = 19, ["name"] = "mcl_core:wood", ["z"] = 48, ["meta"] = {["inventory"] = {}, ["fields"] = {}}, ["param2"] = 0, ["param1"] = 0}, {["y"] = 4, ["x"] = 19, ["name"] = "mcl_core:wood", ["z"] = 49, ["meta"] = {["inventory"] = {}, ["fields"] = {}}, ["param2"] = 0, ["param1"] = 0}, {["y"] = 4, ["x"] = 19, ["name"] = "mcl_core:tree", ["z"] = 50, ["meta"] = {["inventory"] = {}, ["fields"] = {}}, ["param2"] = 1, ["param1"] = 0}, {["y"] = 0, ["x"] = 20, ["name"] = "mcl_core:cobble", ["z"] = 46, ["meta"] = {["inventory"] = {}, ["fields"] = {}}, ["param2"] = 0, ["param1"] = 0}, {["y"] = 0, ["x"] = 20, ["name"] = "mcl_core:dirt", ["z"] = 47, ["meta"] = {["inventory"] = {}, ["fields"] = {}}, ["param2"] = 0, ["param1"] = 0}, {["y"] = 0, ["x"] = 20, ["name"] = "mcl_core:dirt", ["z"] = 48, ["meta"] = {["inventory"] = {}, ["fields"] = {}}, ["param2"] = 0, ["param1"] = 0}, {["y"] = 0, ["x"] = 20, ["name"] = "mcl_core:dirt", ["z"] = 49, ["meta"] = {["inventory"] = {}, ["fields"] = {}}, ["param2"] = 0, ["param1"] = 0}, {["y"] = 0, ["x"] = 20, ["name"] = "mcl_core:cobble", ["z"] = 50, ["meta"] = {["inventory"] = {}, ["fields"] = {}}, ["param2"] = 0, ["param1"] = 0}, {["y"] = 0, ["x"] = 20, ["name"] = "stairs:stair_cobble", ["z"] = 51, ["meta"] = {["inventory"] = {}, ["fields"] = {}}, ["param2"] = 2, ["param1"] = 141}, {["y"] = 0, ["x"] = 20, ["name"] = "mcl_core:cobble", ["z"] = 54, ["meta"] = {["inventory"] = {}, ["fields"] = {}}, ["param2"] = 0, ["param1"] = 0}, {["y"] = 0, ["x"] = 20, ["name"] = "mcl_core:cobble", ["z"] = 55, ["meta"] = {["inventory"] = {}, ["fields"] = {}}, ["param2"] = 0, ["param1"] = 0}, {["y"] = 0, ["x"] = 20, ["name"] = "mcl_core:cobble", ["z"] = 56, ["meta"] = {["inventory"] = {}, ["fields"] = {}}, ["param2"] = 0, ["param1"] = 0}, {["y"] = 0, ["x"] = 20, ["name"] = "mcl_core:cobble", ["z"] = 57, ["meta"] = {["inventory"] = {}, ["fields"] = {}}, ["param2"] = 0, ["param1"] = 0}, {["y"] = 0, ["x"] = 20, ["name"] = "mcl_core:cobble", ["z"] = 58, ["meta"] = {["inventory"] = {}, ["fields"] = {}}, ["param2"] = 0, ["param1"] = 0}, {["y"] = 1, ["x"] = 20, ["name"] = "mcl_core:wood", ["z"] = 46, ["meta"] = {["inventory"] = {}, ["fields"] = {}}, ["param2"] = 0, ["param1"] = 0}, {["y"] = 1, ["x"] = 20, ["name"] = "mcl_doors:wooden_door_b_1", ["z"] = 50, ["meta"] = {["inventory"] = {}, ["fields"] = {}}, ["param2"] = 2, ["param1"] = 173}, {["y"] = 1, ["x"] = 20, ["name"] = "mcl_core:cobble", ["z"] = 54, ["meta"] = {["inventory"] = {}, ["fields"] = {}}, ["param2"] = 0, ["param1"] = 0}, {["y"] = 1, ["x"] = 20, ["name"] = "mcl_core:wood", ["z"] = 55, ["meta"] = {["inventory"] = {}, ["fields"] = {}}, ["param2"] = 0, ["param1"] = 0}, {["y"] = 1, ["x"] = 20, ["name"] = "mcl_core:wood", ["z"] = 56, ["meta"] = {["inventory"] = {}, ["fields"] = {}}, ["param2"] = 0, ["param1"] = 0}, {["y"] = 1, ["x"] = 20, ["name"] = "mcl_core:wood", ["z"] = 57, ["meta"] = {["inventory"] = {}, ["fields"] = {}}, ["param2"] = 0, ["param1"] = 0}, {["y"] = 1, ["x"] = 20, ["name"] = "mcl_core:cobble", ["z"] = 58, ["meta"] = {["inventory"] = {}, ["fields"] = {}}, ["param2"] = 0, ["param1"] = 0}, {["y"] = 2, ["x"] = 20, ["name"] = "xpanes:pane_natural", ["z"] = 46, ["meta"] = {["inventory"] = {}, ["fields"] = {}}, ["param2"] = 0, ["param1"] = 157}, {["y"] = 2, ["x"] = 20, ["name"] = "mcl_doors:wooden_door_t_1", ["z"] = 50, ["meta"] = {["inventory"] = {}, ["fields"] = {}}, ["param2"] = 2, ["param1"] = 189}, {["y"] = 2, ["x"] = 20, ["name"] = "mcl_core:cobble", ["z"] = 54, ["meta"] = {["inventory"] = {}, ["fields"] = {}}, ["param2"] = 0, ["param1"] = 0}, {["y"] = 2, ["x"] = 20, ["name"] = "mcl_core:wood", ["z"] = 55, ["meta"] = {["inventory"] = {}, ["fields"] = {}}, ["param2"] = 0, ["param1"] = 0}, {["y"] = 2, ["x"] = 20, ["name"] = "xpanes:pane_natural", ["z"] = 56, ["meta"] = {["inventory"] = {}, ["fields"] = {}}, ["param2"] = 0, ["param1"] = 157}, {["y"] = 2, ["x"] = 20, ["name"] = "mcl_core:wood", ["z"] = 57, ["meta"] = {["inventory"] = {}, ["fields"] = {}}, ["param2"] = 0, ["param1"] = 0}, {["y"] = 2, ["x"] = 20, ["name"] = "mcl_core:cobble", ["z"] = 58, ["meta"] = {["inventory"] = {}, ["fields"] = {}}, ["param2"] = 0, ["param1"] = 0}, {["y"] = 3, ["x"] = 20, ["name"] = "mcl_core:wood", ["z"] = 46, ["meta"] = {["inventory"] = {}, ["fields"] = {}}, ["param2"] = 0, ["param1"] = 0}, {["y"] = 3, ["x"] = 20, ["name"] = "mcl_torches:torch_wall", ["z"] = 49, ["meta"] = {["inventory"] = {}, ["fields"] = {}}, ["param2"] = 0, ["param1"] = 0}, {["y"] = 3, ["x"] = 20, ["name"] = "mcl_core:wood", ["z"] = 50, ["meta"] = {["inventory"] = {}, ["fields"] = {}}, ["param2"] = 0, ["param1"] = 0}, {["y"] = 3, ["x"] = 20, ["name"] = "mcl_core:cobble", ["z"] = 54, ["meta"] = {["inventory"] = {}, ["fields"] = {}}, ["param2"] = 0, ["param1"] = 0}, {["y"] = 3, ["x"] = 20, ["name"] = "mcl_core:wood", ["z"] = 55, ["meta"] = {["inventory"] = {}, ["fields"] = {}}, ["param2"] = 0, ["param1"] = 0}, {["y"] = 3, ["x"] = 20, ["name"] = "mcl_core:wood", ["z"] = 56, ["meta"] = {["inventory"] = {}, ["fields"] = {}}, ["param2"] = 0, ["param1"] = 0}, {["y"] = 3, ["x"] = 20, ["name"] = "mcl_core:wood", ["z"] = 57, ["meta"] = {["inventory"] = {}, ["fields"] = {}}, ["param2"] = 0, ["param1"] = 0}, {["y"] = 3, ["x"] = 20, ["name"] = "mcl_core:cobble", ["z"] = 58, ["meta"] = {["inventory"] = {}, ["fields"] = {}}, ["param2"] = 0, ["param1"] = 0}, {["y"] = 4, ["x"] = 20, ["name"] = "mcl_core:tree", ["z"] = 46, ["meta"] = {["inventory"] = {}, ["fields"] = {}}, ["param2"] = 3, ["param1"] = 0}, {["y"] = 4, ["x"] = 20, ["name"] = "mcl_core:wood", ["z"] = 47, ["meta"] = {["inventory"] = {}, ["fields"] = {}}, ["param2"] = 0, ["param1"] = 0}, {["y"] = 4, ["x"] = 20, ["name"] = "mcl_core:wood", ["z"] = 48, ["meta"] = {["inventory"] = {}, ["fields"] = {}}, ["param2"] = 0, ["param1"] = 0}, {["y"] = 4, ["x"] = 20, ["name"] = "mcl_core:wood", ["z"] = 49, ["meta"] = {["inventory"] = {}, ["fields"] = {}}, ["param2"] = 0, ["param1"] = 0}, {["y"] = 4, ["x"] = 20, ["name"] = "mcl_core:tree", ["z"] = 50, ["meta"] = {["inventory"] = {}, ["fields"] = {}}, ["param2"] = 2, ["param1"] = 0}, {["y"] = 4, ["x"] = 20, ["name"] = "mcl_core:tree", ["z"] = 54, ["meta"] = {["inventory"] = {}, ["fields"] = {}}, ["param2"] = 0, ["param1"] = 0}, {["y"] = 4, ["x"] = 20, ["name"] = "mcl_core:tree", ["z"] = 55, ["meta"] = {["inventory"] = {}, ["fields"] = {}}, ["param2"] = 0, ["param1"] = 0}, {["y"] = 4, ["x"] = 20, ["name"] = "mcl_core:tree", ["z"] = 56, ["meta"] = {["inventory"] = {}, ["fields"] = {}}, ["param2"] = 0, ["param1"] = 0}, {["y"] = 4, ["x"] = 20, ["name"] = "mcl_core:tree", ["z"] = 57, ["meta"] = {["inventory"] = {}, ["fields"] = {}}, ["param2"] = 0, ["param1"] = 0}, {["y"] = 4, ["x"] = 20, ["name"] = "mcl_core:tree", ["z"] = 58, ["meta"] = {["inventory"] = {}, ["fields"] = {}}, ["param2"] = 0, ["param1"] = 0}, {["y"] = 0, ["x"] = 21, ["name"] = "mcl_core:cobble", ["z"] = 46, ["meta"] = {["inventory"] = {}, ["fields"] = {}}, ["param2"] = 0, ["param1"] = 0}, {["y"] = 0, ["x"] = 21, ["name"] = "mcl_core:dirt", ["z"] = 47, ["meta"] = {["inventory"] = {}, ["fields"] = {}}, ["param2"] = 0, ["param1"] = 0}, {["y"] = 0, ["x"] = 21, ["name"] = "mcl_core:dirt", ["z"] = 48, ["meta"] = {["inventory"] = {}, ["fields"] = {}}, ["param2"] = 0, ["param1"] = 0}, {["y"] = 0, ["x"] = 21, ["name"] = "mcl_core:dirt", ["z"] = 49, ["meta"] = {["inventory"] = {}, ["fields"] = {}}, ["param2"] = 0, ["param1"] = 0}, {["y"] = 0, ["x"] = 21, ["name"] = "mcl_core:cobble", ["z"] = 50, ["meta"] = {["inventory"] = {}, ["fields"] = {}}, ["param2"] = 0, ["param1"] = 0}, {["y"] = 0, ["x"] = 21, ["name"] = "mcl_core:cobble", ["z"] = 54, ["meta"] = {["inventory"] = {}, ["fields"] = {}}, ["param2"] = 0, ["param1"] = 0}, {["y"] = 0, ["x"] = 21, ["name"] = "mcl_core:dirt", ["z"] = 55, ["meta"] = {["inventory"] = {}, ["fields"] = {}}, ["param2"] = 0, ["param1"] = 0}, {["y"] = 0, ["x"] = 21, ["name"] = "mcl_core:dirt", ["z"] = 56, ["meta"] = {["inventory"] = {}, ["fields"] = {}}, ["param2"] = 0, ["param1"] = 0}, {["y"] = 0, ["x"] = 21, ["name"] = "mcl_core:dirt", ["z"] = 57, ["meta"] = {["inventory"] = {}, ["fields"] = {}}, ["param2"] = 0, ["param1"] = 0}, {["y"] = 0, ["x"] = 21, ["name"] = "mcl_core:cobble", ["z"] = 58, ["meta"] = {["inventory"] = {}, ["fields"] = {}}, ["param2"] = 0, ["param1"] = 0}, {["y"] = 1, ["x"] = 21, ["name"] = "mcl_core:wood", ["z"] = 46, ["meta"] = {["inventory"] = {}, ["fields"] = {}}, ["param2"] = 0, ["param1"] = 0}, {["y"] = 1, ["x"] = 21, ["name"] = "mcl_core:wood", ["z"] = 50, ["meta"] = {["inventory"] = {}, ["fields"] = {}}, ["param2"] = 0, ["param1"] = 0}, {["y"] = 1, ["x"] = 21, ["name"] = "mcl_core:wood", ["z"] = 54, ["meta"] = {["inventory"] = {}, ["fields"] = {}}, ["param2"] = 0, ["param1"] = 0}, {["y"] = 1, ["x"] = 21, ["name"] = "mcl_core:wood", ["z"] = 58, ["meta"] = {["inventory"] = {}, ["fields"] = {}}, ["param2"] = 0, ["param1"] = 0}, {["y"] = 2, ["x"] = 21, ["name"] = "mcl_core:wood", ["z"] = 46, ["meta"] = {["inventory"] = {}, ["fields"] = {}}, ["param2"] = 0, ["param1"] = 0}, {["y"] = 2, ["x"] = 21, ["name"] = "mcl_core:wood", ["z"] = 50, ["meta"] = {["inventory"] = {}, ["fields"] = {}}, ["param2"] = 0, ["param1"] = 0}, {["y"] = 2, ["x"] = 21, ["name"] = "mcl_core:wood", ["z"] = 54, ["meta"] = {["inventory"] = {}, ["fields"] = {}}, ["param2"] = 0, ["param1"] = 0}, {["y"] = 2, ["x"] = 21, ["name"] = "mcl_core:wood", ["z"] = 58, ["meta"] = {["inventory"] = {}, ["fields"] = {}}, ["param2"] = 0, ["param1"] = 0}, {["y"] = 3, ["x"] = 21, ["name"] = "mcl_torches:torch_wall", ["z"] = 32, ["meta"] = {["inventory"] = {}, ["fields"] = {}}, ["param2"] = 1, ["param1"] = 15}, {["y"] = 3, ["x"] = 21, ["name"] = "mcl_core:wood", ["z"] = 46, ["meta"] = {["inventory"] = {}, ["fields"] = {}}, ["param2"] = 0, ["param1"] = 0}, {["y"] = 3, ["x"] = 21, ["name"] = "mcl_core:wood", ["z"] = 50, ["meta"] = {["inventory"] = {}, ["fields"] = {}}, ["param2"] = 0, ["param1"] = 0}, {["y"] = 3, ["x"] = 21, ["name"] = "mcl_core:wood", ["z"] = 54, ["meta"] = {["inventory"] = {}, ["fields"] = {}}, ["param2"] = 0, ["param1"] = 0}, {["y"] = 3, ["x"] = 21, ["name"] = "mcl_core:wood", ["z"] = 58, ["meta"] = {["inventory"] = {}, ["fields"] = {}}, ["param2"] = 0, ["param1"] = 0}, {["y"] = 4, ["x"] = 21, ["name"] = "mcl_core:tree", ["z"] = 46, ["meta"] = {["inventory"] = {}, ["fields"] = {}}, ["param2"] = 3, ["param1"] = 0}, {["y"] = 4, ["x"] = 21, ["name"] = "mcl_core:wood", ["z"] = 47, ["meta"] = {["inventory"] = {}, ["fields"] = {}}, ["param2"] = 0, ["param1"] = 0}, {["y"] = 4, ["x"] = 21, ["name"] = "mcl_core:wood", ["z"] = 48, ["meta"] = {["inventory"] = {}, ["fields"] = {}}, ["param2"] = 0, ["param1"] = 0}, {["y"] = 4, ["x"] = 21, ["name"] = "mcl_core:wood", ["z"] = 49, ["meta"] = {["inventory"] = {}, ["fields"] = {}}, ["param2"] = 0, ["param1"] = 0}, {["y"] = 4, ["x"] = 21, ["name"] = "mcl_core:tree", ["z"] = 50, ["meta"] = {["inventory"] = {}, ["fields"] = {}}, ["param2"] = 2, ["param1"] = 0}, {["y"] = 4, ["x"] = 21, ["name"] = "mcl_core:tree", ["z"] = 54, ["meta"] = {["inventory"] = {}, ["fields"] = {}}, ["param2"] = 0, ["param1"] = 0}, {["y"] = 4, ["x"] = 21, ["name"] = "mcl_core:wood", ["z"] = 55, ["meta"] = {["inventory"] = {}, ["fields"] = {}}, ["param2"] = 0, ["param1"] = 0}, {["y"] = 4, ["x"] = 21, ["name"] = "mcl_core:wood", ["z"] = 56, ["meta"] = {["inventory"] = {}, ["fields"] = {}}, ["param2"] = 0, ["param1"] = 0}, {["y"] = 4, ["x"] = 21, ["name"] = "mcl_core:wood", ["z"] = 57, ["meta"] = {["inventory"] = {}, ["fields"] = {}}, ["param2"] = 0, ["param1"] = 0}, {["y"] = 4, ["x"] = 21, ["name"] = "mcl_core:tree", ["z"] = 58, ["meta"] = {["inventory"] = {}, ["fields"] = {}}, ["param2"] = 0, ["param1"] = 0}, {["y"] = 0, ["x"] = 22, ["name"] = "mcl_fences:fence", ["z"] = 32, ["meta"] = {["inventory"] = {}, ["fields"] = {}}, ["param2"] = 0, ["param1"] = 157}, {["y"] = 0, ["x"] = 22, ["name"] = "mcl_core:cobble", ["z"] = 46, ["meta"] = {["inventory"] = {}, ["fields"] = {}}, ["param2"] = 0, ["param1"] = 0}, {["y"] = 0, ["x"] = 22, ["name"] = "mcl_core:cobble", ["z"] = 47, ["meta"] = {["inventory"] = {}, ["fields"] = {}}, ["param2"] = 0, ["param1"] = 0}, {["y"] = 0, ["x"] = 22, ["name"] = "mcl_core:cobble", ["z"] = 48, ["meta"] = {["inventory"] = {}, ["fields"] = {}}, ["param2"] = 0, ["param1"] = 0}, {["y"] = 0, ["x"] = 22, ["name"] = "mcl_core:cobble", ["z"] = 49, ["meta"] = {["inventory"] = {}, ["fields"] = {}}, ["param2"] = 0, ["param1"] = 0}, {["y"] = 0, ["x"] = 22, ["name"] = "mcl_core:cobble", ["z"] = 50, ["meta"] = {["inventory"] = {}, ["fields"] = {}}, ["param2"] = 0, ["param1"] = 0}, {["y"] = 0, ["x"] = 22, ["name"] = "stairs:stair_cobble", ["z"] = 53, ["meta"] = {["inventory"] = {}, ["fields"] = {}}, ["param2"] = 0, ["param1"] = 141}, {["y"] = 0, ["x"] = 22, ["name"] = "mcl_core:cobble", ["z"] = 54, ["meta"] = {["inventory"] = {}, ["fields"] = {}}, ["param2"] = 0, ["param1"] = 0}, {["y"] = 0, ["x"] = 22, ["name"] = "mcl_core:dirt", ["z"] = 55, ["meta"] = {["inventory"] = {}, ["fields"] = {}}, ["param2"] = 0, ["param1"] = 0}, {["y"] = 0, ["x"] = 22, ["name"] = "mcl_core:dirt", ["z"] = 56, ["meta"] = {["inventory"] = {}, ["fields"] = {}}, ["param2"] = 0, ["param1"] = 0}, {["y"] = 0, ["x"] = 22, ["name"] = "mcl_core:dirt", ["z"] = 57, ["meta"] = {["inventory"] = {}, ["fields"] = {}}, ["param2"] = 0, ["param1"] = 0}, {["y"] = 0, ["x"] = 22, ["name"] = "mcl_core:cobble", ["z"] = 58, ["meta"] = {["inventory"] = {}, ["fields"] = {}}, ["param2"] = 0, ["param1"] = 0}, {["y"] = 1, ["x"] = 22, ["name"] = "mcl_fences:fence", ["z"] = 32, ["meta"] = {["inventory"] = {}, ["fields"] = {}}, ["param2"] = 0, ["param1"] = 173}, {["y"] = 1, ["x"] = 22, ["name"] = "mcl_core:cobble", ["z"] = 46, ["meta"] = {["inventory"] = {}, ["fields"] = {}}, ["param2"] = 0, ["param1"] = 0}, {["y"] = 1, ["x"] = 22, ["name"] = "mcl_core:wood", ["z"] = 47, ["meta"] = {["inventory"] = {}, ["fields"] = {}}, ["param2"] = 0, ["param1"] = 0}, {["y"] = 1, ["x"] = 22, ["name"] = "mcl_core:wood", ["z"] = 48, ["meta"] = {["inventory"] = {}, ["fields"] = {}}, ["param2"] = 0, ["param1"] = 0}, {["y"] = 1, ["x"] = 22, ["name"] = "mcl_core:wood", ["z"] = 49, ["meta"] = {["inventory"] = {}, ["fields"] = {}}, ["param2"] = 0, ["param1"] = 0}, {["y"] = 1, ["x"] = 22, ["name"] = "mcl_core:cobble", ["z"] = 50, ["meta"] = {["inventory"] = {}, ["fields"] = {}}, ["param2"] = 0, ["param1"] = 0}, {["y"] = 1, ["x"] = 22, ["name"] = "mcl_doors:wooden_door_b_1", ["z"] = 54, ["meta"] = {["inventory"] = {}, ["fields"] = {}}, ["param2"] = 0, ["param1"] = 173}, {["y"] = 1, ["x"] = 22, ["name"] = "mcl_core:wood", ["z"] = 58, ["meta"] = {["inventory"] = {}, ["fields"] = {}}, ["param2"] = 0, ["param1"] = 0}, {["y"] = 2, ["x"] = 22, ["name"] = "mcl_fences:fence", ["z"] = 32, ["meta"] = {["inventory"] = {}, ["fields"] = {}}, ["param2"] = 0, ["param1"] = 189}, {["y"] = 2, ["x"] = 22, ["name"] = "mcl_core:cobble", ["z"] = 46, ["meta"] = {["inventory"] = {}, ["fields"] = {}}, ["param2"] = 0, ["param1"] = 0}, {["y"] = 2, ["x"] = 22, ["name"] = "mcl_core:wood", ["z"] = 47, ["meta"] = {["inventory"] = {}, ["fields"] = {}}, ["param2"] = 0, ["param1"] = 0}, {["y"] = 2, ["x"] = 22, ["name"] = "xpanes:pane_natural", ["z"] = 48, ["meta"] = {["inventory"] = {}, ["fields"] = {}}, ["param2"] = 0, ["param1"] = 157}, {["y"] = 2, ["x"] = 22, ["name"] = "mcl_core:wood", ["z"] = 49, ["meta"] = {["inventory"] = {}, ["fields"] = {}}, ["param2"] = 0, ["param1"] = 0}, {["y"] = 2, ["x"] = 22, ["name"] = "mcl_core:cobble", ["z"] = 50, ["meta"] = {["inventory"] = {}, ["fields"] = {}}, ["param2"] = 0, ["param1"] = 0}, {["y"] = 2, ["x"] = 22, ["name"] = "mcl_doors:wooden_door_t_1", ["z"] = 54, ["meta"] = {["inventory"] = {}, ["fields"] = {}}, ["param2"] = 0, ["param1"] = 189}, {["y"] = 2, ["x"] = 22, ["name"] = "xpanes:pane_natural", ["z"] = 58, ["meta"] = {["inventory"] = {}, ["fields"] = {}}, ["param2"] = 0, ["param1"] = 157}, {["y"] = 3, ["x"] = 22, ["name"] = "mcl_torches:torch_wall", ["z"] = 31, ["meta"] = {["inventory"] = {}, ["fields"] = {}}, ["param2"] = 0, ["param1"] = 15}, {["y"] = 3, ["x"] = 22, ["name"] = "mcl_wool:black", ["z"] = 32, ["meta"] = {["inventory"] = {}, ["fields"] = {}}, ["param2"] = 0, ["param1"] = 0}, {["y"] = 3, ["x"] = 22, ["name"] = "mcl_torches:torch_wall", ["z"] = 33, ["meta"] = {["inventory"] = {}, ["fields"] = {}}, ["param2"] = 2, ["param1"] = 15}, {["y"] = 3, ["x"] = 22, ["name"] = "mcl_core:cobble", ["z"] = 46, ["meta"] = {["inventory"] = {}, ["fields"] = {}}, ["param2"] = 0, ["param1"] = 0}, {["y"] = 3, ["x"] = 22, ["name"] = "mcl_core:wood", ["z"] = 47, ["meta"] = {["inventory"] = {}, ["fields"] = {}}, ["param2"] = 0, ["param1"] = 0}, {["y"] = 3, ["x"] = 22, ["name"] = "mcl_core:wood", ["z"] = 48, ["meta"] = {["inventory"] = {}, ["fields"] = {}}, ["param2"] = 0, ["param1"] = 0}, {["y"] = 3, ["x"] = 22, ["name"] = "mcl_core:wood", ["z"] = 49, ["meta"] = {["inventory"] = {}, ["fields"] = {}}, ["param2"] = 0, ["param1"] = 0}, {["y"] = 3, ["x"] = 22, ["name"] = "mcl_core:cobble", ["z"] = 50, ["meta"] = {["inventory"] = {}, ["fields"] = {}}, ["param2"] = 0, ["param1"] = 0}, {["y"] = 3, ["x"] = 22, ["name"] = "mcl_core:wood", ["z"] = 54, ["meta"] = {["inventory"] = {}, ["fields"] = {}}, ["param2"] = 0, ["param1"] = 0}, {["y"] = 3, ["x"] = 22, ["name"] = "mcl_torches:torch_wall", ["z"] = 55, ["meta"] = {["inventory"] = {}, ["fields"] = {}}, ["param2"] = 2, ["param1"] = 0}, {["y"] = 3, ["x"] = 22, ["name"] = "mcl_core:wood", ["z"] = 58, ["meta"] = {["inventory"] = {}, ["fields"] = {}}, ["param2"] = 0, ["param1"] = 0}, {["y"] = 4, ["x"] = 22, ["name"] = "mcl_core:tree", ["z"] = 46, ["meta"] = {["inventory"] = {}, ["fields"] = {}}, ["param2"] = 0, ["param1"] = 0}, {["y"] = 4, ["x"] = 22, ["name"] = "mcl_core:tree", ["z"] = 47, ["meta"] = {["inventory"] = {}, ["fields"] = {}}, ["param2"] = 0, ["param1"] = 0}, {["y"] = 4, ["x"] = 22, ["name"] = "mcl_core:tree", ["z"] = 48, ["meta"] = {["inventory"] = {}, ["fields"] = {}}, ["param2"] = 0, ["param1"] = 0}, {["y"] = 4, ["x"] = 22, ["name"] = "mcl_core:tree", ["z"] = 49, ["meta"] = {["inventory"] = {}, ["fields"] = {}}, ["param2"] = 0, ["param1"] = 0}, {["y"] = 4, ["x"] = 22, ["name"] = "mcl_core:tree", ["z"] = 50, ["meta"] = {["inventory"] = {}, ["fields"] = {}}, ["param2"] = 2, ["param1"] = 0}, {["y"] = 4, ["x"] = 22, ["name"] = "mcl_core:tree", ["z"] = 54, ["meta"] = {["inventory"] = {}, ["fields"] = {}}, ["param2"] = 0, ["param1"] = 0}, {["y"] = 4, ["x"] = 22, ["name"] = "mcl_core:wood", ["z"] = 55, ["meta"] = {["inventory"] = {}, ["fields"] = {}}, ["param2"] = 0, ["param1"] = 0}, {["y"] = 4, ["x"] = 22, ["name"] = "mcl_core:wood", ["z"] = 56, ["meta"] = {["inventory"] = {}, ["fields"] = {}}, ["param2"] = 0, ["param1"] = 0}, {["y"] = 4, ["x"] = 22, ["name"] = "mcl_core:wood", ["z"] = 57, ["meta"] = {["inventory"] = {}, ["fields"] = {}}, ["param2"] = 0, ["param1"] = 0}, {["y"] = 4, ["x"] = 22, ["name"] = "mcl_core:tree", ["z"] = 58, ["meta"] = {["inventory"] = {}, ["fields"] = {}}, ["param2"] = 0, ["param1"] = 0}, {["y"] = 0, ["x"] = 23, ["name"] = "mcl_core:cobble", ["z"] = 54, ["meta"] = {["inventory"] = {}, ["fields"] = {}}, ["param2"] = 0, ["param1"] = 0}, {["y"] = 0, ["x"] = 23, ["name"] = "mcl_core:dirt", ["z"] = 55, ["meta"] = {["inventory"] = {}, ["fields"] = {}}, ["param2"] = 0, ["param1"] = 0}, {["y"] = 0, ["x"] = 23, ["name"] = "mcl_core:dirt", ["z"] = 56, ["meta"] = {["inventory"] = {}, ["fields"] = {}}, ["param2"] = 0, ["param1"] = 0}, {["y"] = 0, ["x"] = 23, ["name"] = "mcl_core:dirt", ["z"] = 57, ["meta"] = {["inventory"] = {}, ["fields"] = {}}, ["param2"] = 0, ["param1"] = 0}, {["y"] = 0, ["x"] = 23, ["name"] = "mcl_core:cobble", ["z"] = 58, ["meta"] = {["inventory"] = {}, ["fields"] = {}}, ["param2"] = 0, ["param1"] = 0}, {["y"] = 1, ["x"] = 23, ["name"] = "mcl_core:wood", ["z"] = 54, ["meta"] = {["inventory"] = {}, ["fields"] = {}}, ["param2"] = 0, ["param1"] = 0}, {["y"] = 1, ["x"] = 23, ["name"] = "mcl_core:wood", ["z"] = 58, ["meta"] = {["inventory"] = {}, ["fields"] = {}}, ["param2"] = 0, ["param1"] = 0}, {["y"] = 2, ["x"] = 23, ["name"] = "mcl_core:wood", ["z"] = 54, ["meta"] = {["inventory"] = {}, ["fields"] = {}}, ["param2"] = 0, ["param1"] = 0}, {["y"] = 2, ["x"] = 23, ["name"] = "mcl_core:wood", ["z"] = 58, ["meta"] = {["inventory"] = {}, ["fields"] = {}}, ["param2"] = 0, ["param1"] = 0}, {["y"] = 3, ["x"] = 23, ["name"] = "mcl_torches:torch_wall", ["z"] = 32, ["meta"] = {["inventory"] = {}, ["fields"] = {}}, ["param2"] = 3, ["param1"] = 15}, {["y"] = 3, ["x"] = 23, ["name"] = "mcl_core:wood", ["z"] = 54, ["meta"] = {["inventory"] = {}, ["fields"] = {}}, ["param2"] = 0, ["param1"] = 0}, {["y"] = 3, ["x"] = 23, ["name"] = "mcl_core:wood", ["z"] = 58, ["meta"] = {["inventory"] = {}, ["fields"] = {}}, ["param2"] = 0, ["param1"] = 0}, {["y"] = 4, ["x"] = 23, ["name"] = "mcl_core:tree", ["z"] = 54, ["meta"] = {["inventory"] = {}, ["fields"] = {}}, ["param2"] = 0, ["param1"] = 0}, {["y"] = 4, ["x"] = 23, ["name"] = "mcl_core:wood", ["z"] = 55, ["meta"] = {["inventory"] = {}, ["fields"] = {}}, ["param2"] = 0, ["param1"] = 0}, {["y"] = 4, ["x"] = 23, ["name"] = "mcl_core:wood", ["z"] = 56, ["meta"] = {["inventory"] = {}, ["fields"] = {}}, ["param2"] = 0, ["param1"] = 0}, {["y"] = 4, ["x"] = 23, ["name"] = "mcl_core:wood", ["z"] = 57, ["meta"] = {["inventory"] = {}, ["fields"] = {}}, ["param2"] = 0, ["param1"] = 0}, {["y"] = 4, ["x"] = 23, ["name"] = "mcl_core:tree", ["z"] = 58, ["meta"] = {["inventory"] = {}, ["fields"] = {}}, ["param2"] = 0, ["param1"] = 0}, {["y"] = 0, ["x"] = 24, ["name"] = "mcl_core:cobble", ["z"] = 15, ["meta"] = {["inventory"] = {}, ["fields"] = {}}, ["param2"] = 0, ["param1"] = 0}, {["y"] = 0, ["x"] = 24, ["name"] = "mcl_core:cobble", ["z"] = 16, ["meta"] = {["inventory"] = {}, ["fields"] = {}}, ["param2"] = 0, ["param1"] = 0}, {["y"] = 0, ["x"] = 24, ["name"] = "mcl_core:cobble", ["z"] = 17, ["meta"] = {["inventory"] = {}, ["fields"] = {}}, ["param2"] = 0, ["param1"] = 0}, {["y"] = 0, ["x"] = 24, ["name"] = "mcl_core:cobble", ["z"] = 18, ["meta"] = {["inventory"] = {}, ["fields"] = {}}, ["param2"] = 0, ["param1"] = 0}, {["y"] = 0, ["x"] = 24, ["name"] = "mcl_core:cobble", ["z"] = 19, ["meta"] = {["inventory"] = {}, ["fields"] = {}}, ["param2"] = 0, ["param1"] = 0}, {["y"] = 0, ["x"] = 24, ["name"] = "mcl_core:cobble", ["z"] = 20, ["meta"] = {["inventory"] = {}, ["fields"] = {}}, ["param2"] = 0, ["param1"] = 0}, {["y"] = 0, ["x"] = 24, ["name"] = "mcl_core:cobble", ["z"] = 21, ["meta"] = {["inventory"] = {}, ["fields"] = {}}, ["param2"] = 0, ["param1"] = 0}, {["y"] = 0, ["x"] = 24, ["name"] = "mcl_core:cobble", ["z"] = 54, ["meta"] = {["inventory"] = {}, ["fields"] = {}}, ["param2"] = 0, ["param1"] = 0}, {["y"] = 0, ["x"] = 24, ["name"] = "mcl_core:cobble", ["z"] = 55, ["meta"] = {["inventory"] = {}, ["fields"] = {}}, ["param2"] = 0, ["param1"] = 0}, {["y"] = 0, ["x"] = 24, ["name"] = "mcl_core:cobble", ["z"] = 56, ["meta"] = {["inventory"] = {}, ["fields"] = {}}, ["param2"] = 0, ["param1"] = 0}, {["y"] = 0, ["x"] = 24, ["name"] = "mcl_core:cobble", ["z"] = 57, ["meta"] = {["inventory"] = {}, ["fields"] = {}}, ["param2"] = 0, ["param1"] = 0}, {["y"] = 0, ["x"] = 24, ["name"] = "mcl_core:cobble", ["z"] = 58, ["meta"] = {["inventory"] = {}, ["fields"] = {}}, ["param2"] = 0, ["param1"] = 0}, {["y"] = 1, ["x"] = 24, ["name"] = "mcl_core:cobble", ["z"] = 15, ["meta"] = {["inventory"] = {}, ["fields"] = {}}, ["param2"] = 0, ["param1"] = 0}, {["y"] = 1, ["x"] = 24, ["name"] = "mcl_core:cobble", ["z"] = 16, ["meta"] = {["inventory"] = {}, ["fields"] = {}}, ["param2"] = 0, ["param1"] = 0}, {["y"] = 1, ["x"] = 24, ["name"] = "mcl_core:cobble", ["z"] = 17, ["meta"] = {["inventory"] = {}, ["fields"] = {}}, ["param2"] = 0, ["param1"] = 0}, {["y"] = 1, ["x"] = 24, ["name"] = "mcl_core:cobble", ["z"] = 18, ["meta"] = {["inventory"] = {}, ["fields"] = {}}, ["param2"] = 0, ["param1"] = 0}, {["y"] = 1, ["x"] = 24, ["name"] = "mcl_core:cobble", ["z"] = 19, ["meta"] = {["inventory"] = {}, ["fields"] = {}}, ["param2"] = 0, ["param1"] = 0}, {["y"] = 1, ["x"] = 24, ["name"] = "mcl_core:cobble", ["z"] = 20, ["meta"] = {["inventory"] = {}, ["fields"] = {}}, ["param2"] = 0, ["param1"] = 0}, {["y"] = 1, ["x"] = 24, ["name"] = "mcl_core:cobble", ["z"] = 21, ["meta"] = {["inventory"] = {}, ["fields"] = {}}, ["param2"] = 0, ["param1"] = 0}, {["y"] = 1, ["x"] = 24, ["name"] = "mcl_core:cobble", ["z"] = 54, ["meta"] = {["inventory"] = {}, ["fields"] = {}}, ["param2"] = 0, ["param1"] = 0}, {["y"] = 1, ["x"] = 24, ["name"] = "mcl_core:wood", ["z"] = 55, ["meta"] = {["inventory"] = {}, ["fields"] = {}}, ["param2"] = 0, ["param1"] = 0}, {["y"] = 1, ["x"] = 24, ["name"] = "mcl_core:wood", ["z"] = 56, ["meta"] = {["inventory"] = {}, ["fields"] = {}}, ["param2"] = 0, ["param1"] = 0}, {["y"] = 1, ["x"] = 24, ["name"] = "mcl_core:wood", ["z"] = 57, ["meta"] = {["inventory"] = {}, ["fields"] = {}}, ["param2"] = 0, ["param1"] = 0}, {["y"] = 1, ["x"] = 24, ["name"] = "mcl_core:cobble", ["z"] = 58, ["meta"] = {["inventory"] = {}, ["fields"] = {}}, ["param2"] = 0, ["param1"] = 0}, {["y"] = 2, ["x"] = 24, ["name"] = "mcl_core:cobble", ["z"] = 15, ["meta"] = {["inventory"] = {}, ["fields"] = {}}, ["param2"] = 0, ["param1"] = 0}, {["y"] = 2, ["x"] = 24, ["name"] = "mcl_core:cobble", ["z"] = 16, ["meta"] = {["inventory"] = {}, ["fields"] = {}}, ["param2"] = 0, ["param1"] = 0}, {["y"] = 2, ["x"] = 24, ["name"] = "mcl_core:cobble", ["z"] = 17, ["meta"] = {["inventory"] = {}, ["fields"] = {}}, ["param2"] = 0, ["param1"] = 0}, {["y"] = 2, ["x"] = 24, ["name"] = "mcl_core:cobble", ["z"] = 18, ["meta"] = {["inventory"] = {}, ["fields"] = {}}, ["param2"] = 0, ["param1"] = 0}, {["y"] = 2, ["x"] = 24, ["name"] = "mcl_core:cobble", ["z"] = 19, ["meta"] = {["inventory"] = {}, ["fields"] = {}}, ["param2"] = 0, ["param1"] = 0}, {["y"] = 2, ["x"] = 24, ["name"] = "mcl_core:cobble", ["z"] = 20, ["meta"] = {["inventory"] = {}, ["fields"] = {}}, ["param2"] = 0, ["param1"] = 0}, {["y"] = 2, ["x"] = 24, ["name"] = "mcl_core:cobble", ["z"] = 21, ["meta"] = {["inventory"] = {}, ["fields"] = {}}, ["param2"] = 0, ["param1"] = 0}, {["y"] = 2, ["x"] = 24, ["name"] = "mcl_core:cobble", ["z"] = 54, ["meta"] = {["inventory"] = {}, ["fields"] = {}}, ["param2"] = 0, ["param1"] = 0}, {["y"] = 2, ["x"] = 24, ["name"] = "mcl_core:wood", ["z"] = 55, ["meta"] = {["inventory"] = {}, ["fields"] = {}}, ["param2"] = 0, ["param1"] = 0}, {["y"] = 2, ["x"] = 24, ["name"] = "xpanes:pane_natural", ["z"] = 56, ["meta"] = {["inventory"] = {}, ["fields"] = {}}, ["param2"] = 0, ["param1"] = 157}, {["y"] = 2, ["x"] = 24, ["name"] = "mcl_core:wood", ["z"] = 57, ["meta"] = {["inventory"] = {}, ["fields"] = {}}, ["param2"] = 0, ["param1"] = 0}, {["y"] = 2, ["x"] = 24, ["name"] = "mcl_core:cobble", ["z"] = 58, ["meta"] = {["inventory"] = {}, ["fields"] = {}}, ["param2"] = 0, ["param1"] = 0}, {["y"] = 3, ["x"] = 24, ["name"] = "mcl_core:cobble", ["z"] = 15, ["meta"] = {["inventory"] = {}, ["fields"] = {}}, ["param2"] = 0, ["param1"] = 0}, {["y"] = 3, ["x"] = 24, ["name"] = "mcl_core:cobble", ["z"] = 16, ["meta"] = {["inventory"] = {}, ["fields"] = {}}, ["param2"] = 0, ["param1"] = 0}, {["y"] = 3, ["x"] = 24, ["name"] = "mcl_core:cobble", ["z"] = 17, ["meta"] = {["inventory"] = {}, ["fields"] = {}}, ["param2"] = 0, ["param1"] = 0},