return {{["y"] = 0, ["x"] = 0, ["name"] = "default:gravel", ["z"] = 0, ["meta"] = {["inventory"] = {}, ["fields"] = {}}, ["param2"] = 0, ["param1"] = 0}, {["y"] = 0, ["x"] = 0, ["name"] = "default:gravel", ["z"] = 1, ["meta"] = {["inventory"] = {}, ["fields"] = {}}, ["param2"] = 0, ["param1"] = 0}, {["y"] = 0, ["x"] = 0, ["name"] = "default:gravel", ["z"] = 2, ["meta"] = {["inventory"] = {}, ["fields"] = {}}, ["param2"] = 0, ["param1"] = 0}, {["y"] = 0, ["x"] = 0, ["name"] = "default:gravel", ["z"] = 3, ["meta"] = {["inventory"] = {}, ["fields"] = {}}, ["param2"] = 0, ["param1"] = 0}, {["y"] = 0, ["x"] = 0, ["name"] = "default:gravel", ["z"] = 4, ["meta"] = {["inventory"] = {}, ["fields"] = {}}, ["param2"] = 0, ["param1"] = 0}, {["y"] = 0, ["x"] = 0, ["name"] = "default:gravel", ["z"] = 5, ["meta"] = {["inventory"] = {}, ["fields"] = {}}, ["param2"] = 0, ["param1"] = 0}, {["y"] = 0, ["x"] = 1, ["name"] = "default:gravel", ["z"] = 0, ["meta"] = {["inventory"] = {}, ["fields"] = {}}, ["param2"] = 0, ["param1"] = 0}, {["y"] = 0, ["x"] = 1, ["name"] = "default:gravel", ["z"] = 1, ["meta"] = {["inventory"] = {}, ["fields"] = {}}, ["param2"] = 0, ["param1"] = 0}, {["y"] = 0, ["x"] = 1, ["name"] = "default:cobble", ["z"] = 2, ["meta"] = {["inventory"] = {}, ["fields"] = {}}, ["param2"] = 0, ["param1"] = 0}, {["y"] = 0, ["x"] = 1, ["name"] = "default:cobble", ["z"] = 3, ["meta"] = {["inventory"] = {}, ["fields"] = {}}, ["param2"] = 0, ["param1"] = 0}, {["y"] = 0, ["x"] = 1, ["name"] = "default:gravel", ["z"] = 4, ["meta"] = {["inventory"] = {}, ["fields"] = {}}, ["param2"] = 0, ["param1"] = 0}, {["y"] = 0, ["x"] = 1, ["name"] = "default:gravel", ["z"] = 5, ["meta"] = {["inventory"] = {}, ["fields"] = {}}, ["param2"] = 0, ["param1"] = 0}, {["y"] = 1, ["x"] = 1, ["name"] = "default:cobble", ["z"] = 1, ["meta"] = {["inventory"] = {}, ["fields"] = {}}, ["param2"] = 0, ["param1"] = 0}, {["y"] = 1, ["x"] = 1, ["name"] = "default:cobble", ["z"] = 2, ["meta"] = {["inventory"] = {}, ["fields"] = {}}, ["param2"] = 0, ["param1"] = 0}, {["y"] = 1, ["x"] = 1, ["name"] = "default:cobble", ["z"] = 3, ["meta"] = {["inventory"] = {}, ["fields"] = {}}, ["param2"] = 0, ["param1"] = 0}, {["y"] = 1, ["x"] = 1, ["name"] = "default:cobble", ["z"] = 4, ["meta"] = {["inventory"] = {}, ["fields"] = {}}, ["param2"] = 0, ["param1"] = 0}, {["y"] = 2, ["x"] = 1, ["name"] = "fences:fence_wood", ["z"] = 1, ["meta"] = {["inventory"] = {}, ["fields"] = {}}, ["param2"] = 0, ["param1"] = 45}, {["y"] = 2, ["x"] = 1, ["name"] = "fences:fence_wood", ["z"] = 4, ["meta"] = {["inventory"] = {}, ["fields"] = {}}, ["param2"] = 0, ["param1"] = 93}, {["y"] = 3, ["x"] = 1, ["name"] = "fences:fence_wood", ["z"] = 1, ["meta"] = {["inventory"] = {}, ["fields"] = {}}, ["param2"] = 0, ["param1"] = 61}, {["y"] = 3, ["x"] = 1, ["name"] = "fences:fence_wood", ["z"] = 4, ["meta"] = {["inventory"] = {}, ["fields"] = {}}, ["param2"] = 0, ["param1"] = 109}, {["y"] = 4, ["x"] = 1, ["name"] = "default:cobble", ["z"] = 1, ["meta"] = {["inventory"] = {}, ["fields"] = {}}, ["param2"] = 0, ["param1"] = 0}, {["y"] = 4, ["x"] = 1, ["name"] = "default:cobble", ["z"] = 2, ["meta"] = {["inventory"] = {}, ["fields"] = {}}, ["param2"] = 0, ["param1"] = 0}, {["y"] = 4, ["x"] = 1, ["name"] = "default:cobble", ["z"] = 3, ["meta"] = {["inventory"] = {}, ["fields"] = {}}, ["param2"] = 0, ["param1"] = 0}, {["y"] = 4, ["x"] = 1, ["name"] = "default:cobble", ["z"] = 4, ["meta"] = {["inventory"] = {}, ["fields"] = {}}, ["param2"] = 0, ["param1"] = 0}, {["y"] = 0, ["x"] = 2, ["name"] = "default:gravel", ["z"] = 0, ["meta"] = {["inventory"] = {}, ["fields"] = {}}, ["param2"] = 0, ["param1"] = 0}, {["y"] = 0, ["x"] = 2, ["name"] = "default:cobble", ["z"] = 1, ["meta"] = {["inventory"] = {}, ["fields"] = {}}, ["param2"] = 0, ["param1"] = 0}, {["y"] = 0, ["x"] = 2, ["name"] = "default:water_source", ["z"] = 2, ["meta"] = {["inventory"] = {}, ["fields"] = {}}, ["param2"] = 0, ["param1"] = 10}, {["y"] = 0, ["x"] = 2, ["name"] = "default:water_source", ["z"] = 3, ["meta"] = {["inventory"] = {}, ["fields"] = {}}, ["param2"] = 0, ["param1"] = 26}, {["y"] = 0, ["x"] = 2, ["name"] = "default:cobble", ["z"] = 4, ["meta"] = {["inventory"] = {}, ["fields"] = {}}, ["param2"] = 0, ["param1"] = 0}, {["y"] = 0, ["x"] = 2, ["name"] = "default:gravel", ["z"] = 5, ["meta"] = {["inventory"] = {}, ["fields"] = {}}, ["param2"] = 0, ["param1"] = 0}, {["y"] = 1, ["x"] = 2, ["name"] = "default:cobble", ["z"] = 1, ["meta"] = {["inventory"] = {}, ["fields"] = {}}, ["param2"] = 0, ["param1"] = 0}, {["y"] = 1, ["x"] = 2, ["name"] = "default:water_source", ["z"] = 2, ["meta"] = {["inventory"] = {}, ["fields"] = {}}, ["param2"] = 0, ["param1"] = 27}, {["y"] = 1, ["x"] = 2, ["name"] = "default:water_source", ["z"] = 3, ["meta"] = {["inventory"] = {}, ["fields"] = {}}, ["param2"] = 240, ["param1"] = 43}, {["y"] = 1, ["x"] = 2, ["name"] = "default:cobble", ["z"] = 4, ["meta"] = {["inventory"] = {}, ["fields"] = {}}, ["param2"] = 0, ["param1"] = 0}, {["y"] = 4, ["x"] = 2, ["name"] = "default:cobble", ["z"] = 1, ["meta"] = {["inventory"] = {}, ["fields"] = {}}, ["param2"] = 0, ["param1"] = 0}, {["y"] = 4, ["x"] = 2, ["name"] = "default:cobble", ["z"] = 2, ["meta"] = {["inventory"] = {}, ["fields"] = {}}, ["param2"] = 0, ["param1"] = 0}, {["y"] = 4, ["x"] = 2, ["name"] = "default:cobble", ["z"] = 3, ["meta"] = {["inventory"] = {}, ["fields"] = {}}, ["param2"] = 0, ["param1"] = 0}, {["y"] = 4, ["x"] = 2, ["name"] = "default:cobble", ["z"] = 4, ["meta"] = {["inventory"] = {}, ["fields"] = {}}, ["param2"] = 0, ["param1"] = 0}, {["y"] = 0, ["x"] = 3, ["name"] = "default:gravel", ["z"] = 0, ["meta"] = {["inventory"] = {}, ["fields"] = {}}, ["param2"] = 0, ["param1"] = 0}, {["y"] = 0, ["x"] = 3, ["name"] = "default:cobble", ["z"] = 1, ["meta"] = {["inventory"] = {}, ["fields"] = {}}, ["param2"] = 0, ["param1"] = 0}, {["y"] = 0, ["x"] = 3, ["name"] = "default:water_source", ["z"] = 2, ["meta"] = {["inventory"] = {}, ["fields"] = {}}, ["param2"] = 0, ["param1"] = 10}, {["y"] = 0, ["x"] = 3, ["name"] = "default:water_source", ["z"] = 3, ["meta"] = {["inventory"] = {}, ["fields"] = {}}, ["param2"] = 0, ["param1"] = 10}, {["y"] = 0, ["x"] = 3, ["name"] = "default:cobble", ["z"] = 4, ["meta"] = {["inventory"] = {}, ["fields"] = {}}, ["param2"] = 0, ["param1"] = 0}, {["y"] = 0, ["x"] = 3, ["name"] = "default:gravel", ["z"] = 5, ["meta"] = {["inventory"] = {}, ["fields"] = {}}, ["param2"] = 0, ["param1"] = 0}, {["y"] = 1, ["x"] = 3, ["name"] = "default:cobble", ["z"] = 1, ["meta"] = {["inventory"] = {}, ["fields"] = {}}, ["param2"] = 0, ["param1"] = 0}, {["y"] = 1, ["x"] = 3, ["name"] = "default:water_source", ["z"] = 2, ["meta"] = {["inventory"] = {}, ["fields"] = {}}, ["param2"] = 0, ["param1"] = 11}, {["y"] = 1, ["x"] = 3, ["name"] = "default:water_source", ["z"] = 3, ["meta"] = {["inventory"] = {}, ["fields"] = {}}, ["param2"] = 0, ["param1"] = 27}, {["y"] = 1, ["x"] = 3, ["name"] = "default:cobble", ["z"] = 4, ["meta"] = {["inventory"] = {}, ["fields"] = {}}, ["param2"] = 0, ["param1"] = 0}, {["y"] = 4, ["x"] = 3, ["name"] = "default:cobble", ["z"] = 1, ["meta"] = {["inventory"] = {}, ["fields"] = {}}, ["param2"] = 0, ["param1"] = 0}, {["y"] = 4, ["x"] = 3, ["name"] = "default:cobble", ["z"] = 2, ["meta"] = {["inventory"] = {}, ["fields"] = {}}, ["param2"] = 0, ["param1"] = 0}, {["y"] = 4, ["x"] = 3, ["name"] = "default:cobble", ["z"] = 3, ["meta"] = {["inventory"] = {}, ["fields"] = {}}, ["param2"] = 0, ["param1"] = 0}, {["y"] = 4, ["x"] = 3, ["name"] = "default:cobble", ["z"] = 4, ["meta"] = {["inventory"] = {}, ["fields"] = {}}, ["param2"] = 0, ["param1"] = 0}, {["y"] = 0, ["x"] = 4, ["name"] = "default:gravel", ["z"] = 0, ["meta"] = {["inventory"] = {}, ["fields"] = {}}, ["param2"] = 0, ["param1"] = 0}, {["y"] = 0, ["x"] = 4, ["name"] = "default:gravel", ["z"] = 1, ["meta"] = {["inventory"] = {}, ["fields"] = {}}, ["param2"] = 0, ["param1"] = 0}, {["y"] = 0, ["x"] = 4, ["name"] = "default:cobble", ["z"] = 2, ["meta"] = {["inventory"] = {}, ["fields"] = {}}, ["param2"] = 0, ["param1"] = 0}, {["y"] = 0, ["x"] = 4, ["name"] = "default:cobble", ["z"] = 3, ["meta"] = {["inventory"] = {}, ["fields"] = {}}, ["param2"] = 0, ["param1"] = 0}, {["y"] = 0, ["x"] = 4, ["name"] = "default:gravel", ["z"] = 4, ["meta"] = {["inventory"] = {}, ["fields"] = {}}, ["param2"] = 0, ["param1"] = 0}, {["y"] = 0, ["x"] = 4, ["name"] = "default:gravel", ["z"] = 5, ["meta"] = {["inventory"] = {}, ["fields"] = {}}, ["param2"] = 0, ["param1"] = 0}, {["y"] = 1, ["x"] = 4, ["name"] = "default:cobble", ["z"] = 1, ["meta"] = {["inventory"] = {}, ["fields"] = {}}, ["param2"] = 0, ["param1"] = 0}, {["y"] = 1, ["x"] = 4, ["name"] = "default:cobble", ["z"] = 2, ["meta"] = {["inventory"] = {}, ["fields"] = {}}, ["param2"] = 0, ["param1"] = 0}, {["y"] = 1, ["x"] = 4, ["name"] = "default:cobble", ["z"] = 3, ["meta"] = {["inventory"] = {}, ["fields"] = {}}, ["param2"] = 0, ["param1"] = 0}, {["y"] = 1, ["x"] = 4, ["name"] = "default:cobble", ["z"] = 4, ["meta"] = {["inventory"] = {}, ["fields"] = {}}, ["param2"] = 0, ["param1"] = 0}, {["y"] = 2, ["x"] = 4, ["name"] = "fences:fence_wood", ["z"] = 1, ["meta"] = {["inventory"] = {}, ["fields"] = {}}, ["param2"] = 0, ["param1"] = 13}, {["y"] = 2, ["x"] = 4, ["name"] = "fences:fence_wood", ["z"] = 4, ["meta"] = {["inventory"] = {}, ["fields"] = {}}, ["param2"] = 0, ["param1"] = 45}, {["y"] = 3, ["x"] = 4, ["name"] = "fences:fence_wood", ["z"] = 1, ["meta"] = {["inventory"] = {}, ["fields"] = {}}, ["param2"] = 0, ["param1"] = 13}, {["y"] = 3, ["x"] = 4, ["name"] = "fences:fence_wood", ["z"] = 4, ["meta"] = {["inventory"] = {}, ["fields"] = {}}, ["param2"] = 0, ["param1"] = 61}, {["y"] = 4, ["x"] = 4, ["name"] = "default:cobble", ["z"] = 1, ["meta"] = {["inventory"] = {}, ["fields"] = {}}, ["param2"] = 0, ["param1"] = 0}, {["y"] = 4, ["x"] = 4, ["name"] = "default:cobble", ["z"] = 2, ["meta"] = {["inventory"] = {}, ["fields"] = {}}, ["param2"] = 0, ["param1"] = 0}, {["y"] = 4, ["x"] = 4, ["name"] = "default:cobble", ["z"] = 3, ["meta"] = {["inventory"] = {}, ["fields"] = {}}, ["param2"] = 0, ["param1"] = 0}, {["y"] = 4, ["x"] = 4, ["name"] = "default:cobble", ["z"] = 4, ["meta"] = {["inventory"] = {}, ["fields"] = {}}, ["param2"] = 0, ["param1"] = 0}, {["y"] = 0, ["x"] = 5, ["name"] = "default:gravel", ["z"] = 0, ["meta"] = {["inventory"] = {}, ["fields"] = {}}, ["param2"] = 0, ["param1"] = 0}, {["y"] = 0, ["x"] = 5, ["name"] = "default:gravel", ["z"] = 1, ["meta"] = {["inventory"] = {}, ["fields"] = {}}, ["param2"] = 0, ["param1"] = 0}, {["y"] = 0, ["x"] = 5, ["name"] = "default:gravel", ["z"] = 2, ["meta"] = {["inventory"] = {}, ["fields"] = {}}, ["param2"] = 0, ["param1"] = 0}, {["y"] = 0, ["x"] = 5, ["name"] = "default:gravel", ["z"] = 3, ["meta"] = {["inventory"] = {}, ["fields"] = {}}, ["param2"] = 0, ["param1"] = 0}, {["y"] = 0, ["x"] = 5, ["name"] = "default:gravel", ["z"] = 4, ["meta"] = {["inventory"] = {}, ["fields"] = {}}, ["param2"] = 0, ["param1"] = 0}, {["y"] = 0, ["x"] = 5, ["name"] = "default:gravel", ["z"] = 5, ["meta"] = {["inventory"] = {}, ["fields"] = {}}, ["param2"] = 0, ["param1"] = 0}}