return {{["y"] = 0, ["x"] = 1, ["name"] = "default:cobble", ["z"] = 1, ["meta"] = {["inventory"] = {}, ["fields"] = {}}, ["param2"] = 0, ["param1"] = 0}, {["y"] = 0, ["x"] = 1, ["name"] = "default:cobble", ["z"] = 2, ["meta"] = {["inventory"] = {}, ["fields"] = {}}, ["param2"] = 0, ["param1"] = 0}, {["y"] = 0, ["x"] = 1, ["name"] = "default:cobble", ["z"] = 3, ["meta"] = {["inventory"] = {}, ["fields"] = {}}, ["param2"] = 0, ["param1"] = 0}, {["y"] = 0, ["x"] = 1, ["name"] = "default:cobble", ["z"] = 4, ["meta"] = {["inventory"] = {}, ["fields"] = {}}, ["param2"] = 0, ["param1"] = 0}, {["y"] = 0, ["x"] = 1, ["name"] = "default:cobble", ["z"] = 5, ["meta"] = {["inventory"] = {}, ["fields"] = {}}, ["param2"] = 0, ["param1"] = 0}, {["y"] = 1, ["x"] = 1, ["name"] = "default:cobble", ["z"] = 1, ["meta"] = {["inventory"] = {}, ["fields"] = {}}, ["param2"] = 0, ["param1"] = 0}, {["y"] = 1, ["x"] = 1, ["name"] = "default:wood", ["z"] = 2, ["meta"] = {["inventory"] = {}, ["fields"] = {}}, ["param2"] = 0, ["param1"] = 0}, {["y"] = 1, ["x"] = 1, ["name"] = "default:wood", ["z"] = 3, ["meta"] = {["inventory"] = {}, ["fields"] = {}}, ["param2"] = 0, ["param1"] = 0}, {["y"] = 1, ["x"] = 1, ["name"] = "default:wood", ["z"] = 4, ["meta"] = {["inventory"] = {}, ["fields"] = {}}, ["param2"] = 0, ["param1"] = 0}, {["y"] = 1, ["x"] = 1, ["name"] = "default:cobble", ["z"] = 5, ["meta"] = {["inventory"] = {}, ["fields"] = {}}, ["param2"] = 0, ["param1"] = 0}, {["y"] = 2, ["x"] = 1, ["name"] = "default:cobble", ["z"] = 1, ["meta"] = {["inventory"] = {}, ["fields"] = {}}, ["param2"] = 0, ["param1"] = 0}, {["y"] = 2, ["x"] = 1, ["name"] = "default:wood", ["z"] = 2, ["meta"] = {["inventory"] = {}, ["fields"] = {}}, ["param2"] = 0, ["param1"] = 0}, {["y"] = 2, ["x"] = 1, ["name"] = "xpanes:pane_glass_natural_10", ["z"] = 3, ["meta"] = {["inventory"] = {}, ["fields"] = {}}, ["param2"] = 0, ["param1"] = 77}, {["y"] = 2, ["x"] = 1, ["name"] = "default:wood", ["z"] = 4, ["meta"] = {["inventory"] = {}, ["fields"] = {}}, ["param2"] = 0, ["param1"] = 0}, {["y"] = 2, ["x"] = 1, ["name"] = "default:cobble", ["z"] = 5, ["meta"] = {["inventory"] = {}, ["fields"] = {}}, ["param2"] = 0, ["param1"] = 0}, {["y"] = 3, ["x"] = 1, ["name"] = "default:cobble", ["z"] = 1, ["meta"] = {["inventory"] = {}, ["fields"] = {}}, ["param2"] = 0, ["param1"] = 0}, {["y"] = 3, ["x"] = 1, ["name"] = "default:wood", ["z"] = 2, ["meta"] = {["inventory"] = {}, ["fields"] = {}}, ["param2"] = 0, ["param1"] = 0}, {["y"] = 3, ["x"] = 1, ["name"] = "default:wood", ["z"] = 3, ["meta"] = {["inventory"] = {}, ["fields"] = {}}, ["param2"] = 0, ["param1"] = 0}, {["y"] = 3, ["x"] = 1, ["name"] = "default:wood", ["z"] = 4, ["meta"] = {["inventory"] = {}, ["fields"] = {}}, ["param2"] = 0, ["param1"] = 0}, {["y"] = 3, ["x"] = 1, ["name"] = "default:cobble", ["z"] = 5, ["meta"] = {["inventory"] = {}, ["fields"] = {}}, ["param2"] = 0, ["param1"] = 0}, {["y"] = 4, ["x"] = 1, ["name"] = "default:tree", ["z"] = 1, ["meta"] = {["inventory"] = {}, ["fields"] = {}}, ["param2"] = 2, ["param1"] = 0}, {["y"] = 4, ["x"] = 1, ["name"] = "default:tree", ["z"] = 2, ["meta"] = {["inventory"] = {}, ["fields"] = {}}, ["param2"] = 2, ["param1"] = 0}, {["y"] = 4, ["x"] = 1, ["name"] = "default:tree", ["z"] = 3, ["meta"] = {["inventory"] = {}, ["fields"] = {}}, ["param2"] = 2, ["param1"] = 0}, {["y"] = 4, ["x"] = 1, ["name"] = "default:tree", ["z"] = 4, ["meta"] = {["inventory"] = {}, ["fields"] = {}}, ["param2"] = 0, ["param1"] = 0}, {["y"] = 4, ["x"] = 1, ["name"] = "default:tree", ["z"] = 5, ["meta"] = {["inventory"] = {}, ["fields"] = {}}, ["param2"] = 0, ["param1"] = 0}, {["y"] = 5, ["x"] = 1, ["name"] = "fences:fence_wood_23", ["z"] = 1, ["meta"] = {["inventory"] = {}, ["fields"] = {}}, ["param2"] = 0, ["param1"] = 95}, {["y"] = 5, ["x"] = 1, ["name"] = "fences:fence_wood_3", ["z"] = 2, ["meta"] = {["inventory"] = {}, ["fields"] = {}}, ["param2"] = 0, ["param1"] = 79}, {["y"] = 5, ["x"] = 1, ["name"] = "fences:fence_wood_3", ["z"] = 3, ["meta"] = {["inventory"] = {}, ["fields"] = {}}, ["param2"] = 0, ["param1"] = 63}, {["y"] = 5, ["x"] = 1, ["name"] = "fences:fence_wood_3", ["z"] = 4, ["meta"] = {["inventory"] = {}, ["fields"] = {}}, ["param2"] = 0, ["param1"] = 47}, {["y"] = 5, ["x"] = 1, ["name"] = "fences:fence_wood_22", ["z"] = 5, ["meta"] = {["inventory"] = {}, ["fields"] = {}}, ["param2"] = 0, ["param1"] = 31}, {["y"] = 0, ["x"] = 2, ["name"] = "default:cobble", ["z"] = 1, ["meta"] = {["inventory"] = {}, ["fields"] = {}}, ["param2"] = 0, ["param1"] = 0}, {["y"] = 0, ["x"] = 2, ["name"] = "default:dirt", ["z"] = 2, ["meta"] = {["inventory"] = {}, ["fields"] = {}}, ["param2"] = 0, ["param1"] = 0}, {["y"] = 0, ["x"] = 2, ["name"] = "default:dirt", ["z"] = 3, ["meta"] = {["inventory"] = {}, ["fields"] = {}}, ["param2"] = 0, ["param1"] = 0}, {["y"] = 0, ["x"] = 2, ["name"] = "default:dirt", ["z"] = 4, ["meta"] = {["inventory"] = {}, ["fields"] = {}}, ["param2"] = 0, ["param1"] = 0}, {["y"] = 0, ["x"] = 2, ["name"] = "default:cobble", ["z"] = 5, ["meta"] = {["inventory"] = {}, ["fields"] = {}}, ["param2"] = 0, ["param1"] = 0}, {["y"] = 1, ["x"] = 2, ["name"] = "default:wood", ["z"] = 1, ["meta"] = {["inventory"] = {}, ["fields"] = {}}, ["param2"] = 0, ["param1"] = 0}, {["y"] = 1, ["x"] = 2, ["name"] = "default:wood", ["z"] = 5, ["meta"] = {["inventory"] = {}, ["fields"] = {}}, ["param2"] = 0, ["param1"] = 0}, {["y"] = 2, ["x"] = 2, ["name"] = "default:wood", ["z"] = 1, ["meta"] = {["inventory"] = {}, ["fields"] = {}}, ["param2"] = 0, ["param1"] = 0}, {["y"] = 2, ["x"] = 2, ["name"] = "default:wood", ["z"] = 5, ["meta"] = {["inventory"] = {}, ["fields"] = {}}, ["param2"] = 0, ["param1"] = 0}, {["y"] = 3, ["x"] = 2, ["name"] = "default:wood", ["z"] = 1, ["meta"] = {["inventory"] = {}, ["fields"] = {}}, ["param2"] = 0, ["param1"] = 0}, {["y"] = 3, ["x"] = 2, ["name"] = "default:wood", ["z"] = 5, ["meta"] = {["inventory"] = {}, ["fields"] = {}}, ["param2"] = 0, ["param1"] = 0}, {["y"] = 4, ["x"] = 2, ["name"] = "default:tree", ["z"] = 1, ["meta"] = {["inventory"] = {}, ["fields"] = {}}, ["param2"] = 1, ["param1"] = 0}, {["y"] = 4, ["x"] = 2, ["name"] = "default:wood", ["z"] = 2, ["meta"] = {["inventory"] = {}, ["fields"] = {}}, ["param2"] = 0, ["param1"] = 0}, {["y"] = 4, ["x"] = 2, ["name"] = "default:wood", ["z"] = 3, ["meta"] = {["inventory"] = {}, ["fields"] = {}}, ["param2"] = 0, ["param1"] = 0}, {["y"] = 4, ["x"] = 2, ["name"] = "default:wood", ["z"] = 4, ["meta"] = {["inventory"] = {}, ["fields"] = {}}, ["param2"] = 0, ["param1"] = 0}, {["y"] = 4, ["x"] = 2, ["name"] = "default:tree", ["z"] = 5, ["meta"] = {["inventory"] = {}, ["fields"] = {}}, ["param2"] = 3, ["param1"] = 0}, {["y"] = 5, ["x"] = 2, ["name"] = "fences:fence_wood_32", ["z"] = 1, ["meta"] = {["inventory"] = {}, ["fields"] = {}}, ["param2"] = 0, ["param1"] = 111}, {["y"] = 5, ["x"] = 2, ["name"] = "fences:fence_wood_32", ["z"] = 5, ["meta"] = {["inventory"] = {}, ["fields"] = {}}, ["param2"] = 0, ["param1"] = 47}, {["y"] = 0, ["x"] = 3, ["name"] = "stairs:stair_cobble", ["z"] = 0, ["meta"] = {["inventory"] = {}, ["fields"] = {}}, ["param2"] = 0, ["param1"] = 93}, {["y"] = 0, ["x"] = 3, ["name"] = "default:cobble", ["z"] = 1, ["meta"] = {["inventory"] = {}, ["fields"] = {}}, ["param2"] = 0, ["param1"] = 0}, {["y"] = 0, ["x"] = 3, ["name"] = "default:dirt", ["z"] = 2, ["meta"] = {["inventory"] = {}, ["fields"] = {}}, ["param2"] = 0, ["param1"] = 0}, {["y"] = 0, ["x"] = 3, ["name"] = "default:dirt", ["z"] = 3, ["meta"] = {["inventory"] = {}, ["fields"] = {}}, ["param2"] = 0, ["param1"] = 0}, {["y"] = 0, ["x"] = 3, ["name"] = "default:dirt", ["z"] = 4, ["meta"] = {["inventory"] = {}, ["fields"] = {}}, ["param2"] = 0, ["param1"] = 0}, {["y"] = 0, ["x"] = 3, ["name"] = "default:cobble", ["z"] = 5, ["meta"] = {["inventory"] = {}, ["fields"] = {}}, ["param2"] = 0, ["param1"] = 0}, {["y"] = 1, ["x"] = 3, ["name"] = "doors:door_wood_b_1", ["z"] = 1, ["meta"] = {["inventory"] = {}, ["fields"] = {}}, ["param2"] = 0, ["param1"] = 93}, {["y"] = 1, ["x"] = 3, ["name"] = "default:wood", ["z"] = 5, ["meta"] = {["inventory"] = {}, ["fields"] = {}}, ["param2"] = 0, ["param1"] = 0}, {["y"] = 2, ["x"] = 3, ["name"] = "doors:door_wood_t_1", ["z"] = 1, ["meta"] = {["inventory"] = {}, ["fields"] = {}}, ["param2"] = 0, ["param1"] = 109}, {["y"] = 2, ["x"] = 3, ["name"] = "default:wood", ["z"] = 5, ["meta"] = {["inventory"] = {}, ["fields"] = {}}, ["param2"] = 0, ["param1"] = 0}, {["y"] = 3, ["x"] = 3, ["name"] = "default:wood", ["z"] = 1, ["meta"] = {["inventory"] = {}, ["fields"] = {}}, ["param2"] = 0, ["param1"] = 0}, {["y"] = 3, ["x"] = 3, ["name"] = "default:wood", ["z"] = 5, ["meta"] = {["inventory"] = {}, ["fields"] = {}}, ["param2"] = 0, ["param1"] = 0}, {["y"] = 4, ["x"] = 3, ["name"] = "default:tree", ["z"] = 1, ["meta"] = {["inventory"] = {}, ["fields"] = {}}, ["param2"] = 1, ["param1"] = 0}, {["y"] = 4, ["x"] = 3, ["name"] = "default:wood", ["z"] = 2, ["meta"] = {["inventory"] = {}, ["fields"] = {}}, ["param2"] = 0, ["param1"] = 0}, {["y"] = 4, ["x"] = 3, ["name"] = "default:wood", ["z"] = 3, ["meta"] = {["inventory"] = {}, ["fields"] = {}}, ["param2"] = 0, ["param1"] = 0}, {["y"] = 4, ["x"] = 3, ["name"] = "default:wood", ["z"] = 4, ["meta"] = {["inventory"] = {}, ["fields"] = {}}, ["param2"] = 0, ["param1"] = 0}, {["y"] = 4, ["x"] = 3, ["name"] = "default:tree", ["z"] = 5, ["meta"] = {["inventory"] = {}, ["fields"] = {}}, ["param2"] = 3, ["param1"] = 0}, {["y"] = 5, ["x"] = 3, ["name"] = "fences:fence_wood_32", ["z"] = 1, ["meta"] = {["inventory"] = {}, ["fields"] = {}}, ["param2"] = 0, ["param1"] = 127}, {["y"] = 5, ["x"] = 3, ["name"] = "fences:fence_wood_32", ["z"] = 5, ["meta"] = {["inventory"] = {}, ["fields"] = {}}, ["param2"] = 0, ["param1"] = 63}, {["y"] = 0, ["x"] = 4, ["name"] = "default:cobble", ["z"] = 1, ["meta"] = {["inventory"] = {}, ["fields"] = {}}, ["param2"] = 0, ["param1"] = 0}, {["y"] = 0, ["x"] = 4, ["name"] = "default:dirt", ["z"] = 2, ["meta"] = {["inventory"] = {}, ["fields"] = {}}, ["param2"] = 0, ["param1"] = 0}, {["y"] = 0, ["x"] = 4, ["name"] = "default:dirt", ["z"] = 3, ["meta"] = {["inventory"] = {}, ["fields"] = {}}, ["param2"] = 0, ["param1"] = 0}, {["y"] = 0, ["x"] = 4, ["name"] = "default:dirt", ["z"] = 4, ["meta"] = {["inventory"] = {}, ["fields"] = {}}, ["param2"] = 0, ["param1"] = 0}, {["y"] = 0, ["x"] = 4, ["name"] = "default:cobble", ["z"] = 5, ["meta"] = {["inventory"] = {}, ["fields"] = {}}, ["param2"] = 0, ["param1"] = 0}, {["y"] = 1, ["x"] = 4, ["name"] = "default:wood", ["z"] = 1, ["meta"] = {["inventory"] = {}, ["fields"] = {}}, ["param2"] = 0, ["param1"] = 0}, {["y"] = 1, ["x"] = 4, ["name"] = "default:ladder", ["z"] = 4, ["meta"] = {["inventory"] = {}, ["fields"] = {}}, ["param2"] = 4, ["param1"] = 90}, {["y"] = 1, ["x"] = 4, ["name"] = "default:wood", ["z"] = 5, ["meta"] = {["inventory"] = {}, ["fields"] = {}}, ["param2"] = 0, ["param1"] = 0}, {["y"] = 2, ["x"] = 4, ["name"] = "default:wood", ["z"] = 1, ["meta"] = {["inventory"] = {}, ["fields"] = {}}, ["param2"] = 0, ["param1"] = 0}, {["y"] = 2, ["x"] = 4, ["name"] = "default:ladder", ["z"] = 4, ["meta"] = {["inventory"] = {}, ["fields"] = {}}, ["param2"] = 4, ["param1"] = 107}, {["y"] = 2, ["x"] = 4, ["name"] = "default:wood", ["z"] = 5, ["meta"] = {["inventory"] = {}, ["fields"] = {}}, ["param2"] = 0, ["param1"] = 0}, {["y"] = 3, ["x"] = 4, ["name"] = "default:wood", ["z"] = 1, ["meta"] = {["inventory"] = {}, ["fields"] = {}}, ["param2"] = 0, ["param1"] = 0}, {["y"] = 3, ["x"] = 4, ["name"] = "default:ladder", ["z"] = 4, ["meta"] = {["inventory"] = {}, ["fields"] = {}}, ["param2"] = 4, ["param1"] = 92}, {["y"] = 3, ["x"] = 4, ["name"] = "default:wood", ["z"] = 5, ["meta"] = {["inventory"] = {}, ["fields"] = {}}, ["param2"] = 0, ["param1"] = 0}, {["y"] = 4, ["x"] = 4, ["name"] = "default:tree", ["z"] = 1, ["meta"] = {["inventory"] = {}, ["fields"] = {}}, ["param2"] = 1, ["param1"] = 0}, {["y"] = 4, ["x"] = 4, ["name"] = "default:wood", ["z"] = 2, ["meta"] = {["inventory"] = {}, ["fields"] = {}}, ["param2"] = 0, ["param1"] = 0}, {["y"] = 4, ["x"] = 4, ["name"] = "default:wood", ["z"] = 3, ["meta"] = {["inventory"] = {}, ["fields"] = {}}, ["param2"] = 0, ["param1"] = 0}, {["y"] = 4, ["x"] = 4, ["name"] = "default:ladder", ["z"] = 4, ["meta"] = {["inventory"] = {}, ["fields"] = {}}, ["param2"] = 4, ["param1"] = 77}, {["y"] = 4, ["x"] = 4, ["name"] = "default:tree", ["z"] = 5, ["meta"] = {["inventory"] = {}, ["fields"] = {}}, ["param2"] = 0, ["param1"] = 0}, {["y"] = 5, ["x"] = 4, ["name"] = "fences:fence_wood_32", ["z"] = 1, ["meta"] = {["inventory"] = {}, ["fields"] = {}}, ["param2"] = 0, ["param1"] = 143}, {["y"] = 5, ["x"] = 4, ["name"] = "fences:fence_wood_32", ["z"] = 5, ["meta"] = {["inventory"] = {}, ["fields"] = {}}, ["param2"] = 0, ["param1"] = 79}, {["y"] = 0, ["x"] = 5, ["name"] = "default:cobble", ["z"] = 1, ["meta"] = {["inventory"] = {}, ["fields"] = {}}, ["param2"] = 0, ["param1"] = 0}, {["y"] = 0, ["x"] = 5, ["name"] = "default:cobble", ["z"] = 2, ["meta"] = {["inventory"] = {}, ["fields"] = {}}, ["param2"] = 0, ["param1"] = 0}, {["y"] = 0, ["x"] = 5, ["name"] = "default:cobble", ["z"] = 3, ["meta"] = {["inventory"] = {}, ["fields"] = {}}, ["param2"] = 0, ["param1"] = 0}, {["y"] = 0, ["x"] = 5, ["name"] = "default:cobble", ["z"] = 4, ["meta"] = {["inventory"] = {}, ["fields"] = {}}, ["param2"] = 0, ["param1"] = 0}, {["y"] = 0, ["x"] = 5, ["name"] = "default:cobble", ["z"] = 5, ["meta"] = {["inventory"] = {}, ["fields"] = {}}, ["param2"] = 0, ["param1"] = 0}, {["y"] = 1, ["x"] = 5, ["name"] = "default:cobble", ["z"] = 1, ["meta"] = {["inventory"] = {}, ["fields"] = {}}, ["param2"] = 0, ["param1"] = 0}, {["y"] = 1, ["x"] = 5, ["name"] = "default:wood", ["z"] = 2, ["meta"] = {["inventory"] = {}, ["fields"] = {}}, ["param2"] = 0, ["param1"] = 0}, {["y"] = 1, ["x"] = 5, ["name"] = "default:wood", ["z"] = 3, ["meta"] = {["inventory"] = {}, ["fields"] = {}}, ["param2"] = 0, ["param1"] = 0}, {["y"] = 1, ["x"] = 5, ["name"] = "default:wood", ["z"] = 4, ["meta"] = {["inventory"] = {}, ["fields"] = {}}, ["param2"] = 0, ["param1"] = 0}, {["y"] = 1, ["x"] = 5, ["name"] = "default:cobble", ["z"] = 5, ["meta"] = {["inventory"] = {}, ["fields"] = {}}, ["param2"] = 0, ["param1"] = 0}, {["y"] = 2, ["x"] = 5, ["name"] = "default:cobble", ["z"] = 1, ["meta"] = {["inventory"] = {}, ["fields"] = {}}, ["param2"] = 0, ["param1"] = 0}, {["y"] = 2, ["x"] = 5, ["name"] = "default:wood", ["z"] = 2, ["meta"] = {["inventory"] = {}, ["fields"] = {}}, ["param2"] = 0, ["param1"] = 0}, {["y"] = 2, ["x"] = 5, ["name"] = "xpanes:pane_glass_natural_10", ["z"] = 3, ["meta"] = {["inventory"] = {}, ["fields"] = {}}, ["param2"] = 0, ["param1"] = 141}, {["y"] = 2, ["x"] = 5, ["name"] = "default:wood", ["z"] = 4, ["meta"] = {["inventory"] = {}, ["fields"] = {}}, ["param2"] = 0, ["param1"] = 0}, {["y"] = 2, ["x"] = 5, ["name"] = "default:cobble", ["z"] = 5, ["meta"] = {["inventory"] = {}, ["fields"] = {}}, ["param2"] = 0, ["param1"] = 0}, {["y"] = 3, ["x"] = 5, ["name"] = "default:cobble", ["z"] = 1, ["meta"] = {["inventory"] = {}, ["fields"] = {}}, ["param2"] = 0, ["param1"] = 0}, {["y"] = 3, ["x"] = 5, ["name"] = "default:wood", ["z"] = 2, ["meta"] = {["inventory"] = {}, ["fields"] = {}}, ["param2"] = 0, ["param1"] = 0}, {["y"] = 3, ["x"] = 5, ["name"] = "default:wood", ["z"] = 3, ["meta"] = {["inventory"] = {}, ["fields"] = {}}, ["param2"] = 0, ["param1"] = 0}, {["y"] = 3, ["x"] = 5, ["name"] = "default:wood", ["z"] = 4, ["meta"] = {["inventory"] = {}, ["fields"] = {}}, ["param2"] = 0, ["param1"] = 0}, {["y"] = 3, ["x"] = 5, ["name"] = "default:cobble", ["z"] = 5, ["meta"] = {["inventory"] = {}, ["fields"] = {}}, ["param2"] = 0, ["param1"] = 0}, {["y"] = 4, ["x"] = 5, ["name"] = "default:tree", ["z"] = 1, ["meta"] = {["inventory"] = {}, ["fields"] = {}}, ["param2"] = 1, ["param1"] = 0}, {["y"] = 4, ["x"] = 5, ["name"] = "default:tree", ["z"] = 2, ["meta"] = {["inventory"] = {}, ["fields"] = {}}, ["param2"] = 1, ["param1"] = 0}, {["y"] = 4, ["x"] = 5, ["name"] = "default:tree", ["z"] = 3, ["meta"] = {["inventory"] = {}, ["fields"] = {}}, ["param2"] = 0, ["param1"] = 0}, {["y"] = 4, ["x"] = 5, ["name"] = "default:tree", ["z"] = 4, ["meta"] = {["inventory"] = {}, ["fields"] = {}}, ["param2"] = 0, ["param1"] = 0}, {["y"] = 4, ["x"] = 5, ["name"] = "default:tree", ["z"] = 5, ["meta"] = {["inventory"] = {}, ["fields"] = {}}, ["param2"] = 0, ["param1"] = 0}, {["y"] = 5, ["x"] = 5, ["name"] = "fences:fence_wood_13", ["z"] = 1, ["meta"] = {["inventory"] = {}, ["fields"] = {}}, ["param2"] = 0, ["param1"] = 159}, {["y"] = 5, ["x"] = 5, ["name"] = "fences:fence_wood_3", ["z"] = 2, ["meta"] = {["inventory"] = {}, ["fields"] = {}}, ["param2"] = 0, ["param1"] = 143}, {["y"] = 5, ["x"] = 5, ["name"] = "fences:fence_wood_3", ["z"] = 3, ["meta"] = {["inventory"] = {}, ["fields"] = {}}, ["param2"] = 0, ["param1"] = 127}, {["y"] = 5, ["x"] = 5, ["name"] = "fences:fence_wood_3", ["z"] = 4, ["meta"] = {["inventory"] = {}, ["fields"] = {}}, ["param2"] = 0, ["param1"] = 111}, {["y"] = 5, ["x"] = 5, ["name"] = "fences:fence_wood_12", ["z"] = 5, ["meta"] = {["inventory"] = {}, ["fields"] = {}}, ["param2"] = 0, ["param1"] = 95}}